Workbook

Sheet БДДС
A1: Бюджет движения денежных средств 2021г. Чтобы пользоваться таблицей, сделайте себе ее копию на свой гугл-диск
A2: Наименование статьи | B2: янв | C2: фев | D2: мар | E2: апр | F2: май | G2: июн | H2: июл | I2: авг | J2: сен | K2: окт | L2: ноя | M2: дек | N2: ГОД
A3: Остаток денежных средств на начало периода | C3: =B98 -> 0 | D3: =C98 -> 0 | E3: =D98 -> 0 | F3: =E98 -> 0 | G3: =F98 -> 0 | H3: =G98 -> 0 | I3: =H98 -> 0 | J3: =I98 -> 0 | ... M3: =L98 -> 0 | N3: =B3
A4: Поступления по операционной деятельности | B4: =B5+B6 -> 0 | C4: =C5+C6 -> 0 | D4: =D5+D6 -> 0 | E4: =E5+E6 -> 0 | F4: =F5+F6 -> 0 | G4: =G5+G6 -> 0 | H4: =H5+H6 -> 0 | I4: =I5+I6 -> 0 | ... M4: =M5+M6 -> 0 | N4: =B4+C4+D4+E4+F4+G4+H4+I4+J4+K4+L4+M4 -> 0
A5: Поступления от реализации товаров и услуг | N5: =B5+C5+D5+E5+F5+G5+H5+I5+J5+K5+L5+M5 -> 0
A6: Поступления прочие | N6: =B6+C6+D6+E6+F6+G6+H6+I6+J6+K6+L6+M6 -> 0
A7: Выплаты по операционной деятельности | B7: =B8+B9+B13+B16+B21+B26+B27+B31+B30+B35+B40+B44+B47+B52+B62+B66 -> 0 | C7: =C8+C9+C13+C16+C21+C26+C27+C31+C30+C35+C40+C44+C47+C52+C62+C66 -> 0 | D7: =D8+D9+D13+D16+D21+D26+D27+D31+D30+D35+D40+D44+D47+D52+D62+D66 -> 0 | E7: =E8+E9+E13+E16+E21+E26+E27+E31+E30+E35+E40+E44+E47+E52+E62+E66 -> 0 | F7: =F8+F9+F13+F16+F21+F26+F27+F31+F30+F35+F40+F44+F47+F52+F62+F66 -> 0 | G7: =G8+G9+G13+G16+G21+G26+G27+G31+G30+G35+G40+G44+G47+G52+G62+G66 -> 0 | H7: =H8+H9+H13+H16+H21+H26+H27+H31+H30+H35+H40+H44+H47+H52+H62+H66 -> 0 | I7: =I8+I9+I13+I16+I21+I26+I27+I31+I30+I35+I40+I44+I47+I52+I62+I66 -> 0 | ... N7: =N8+N9+N13+N16+N21+N26+N27+N31+N30+N35+N40+N44+N47+N52+N62+N66 -> 0
A8: Выплата заработной платы | N8: =B8+C8+D8+E8+F8+G8+H8+I8+J8+K8+L8+M8 -> 0
A9: Материальные расходы | B9: =B10+B11+B12 -> 0 | C9: =C10+C11+C12 -> 0 | D9: =D10+D11+D12 -> 0 | E9: =E10+E11+E12 -> 0 | F9: =F10+F11+F12 -> 0 | G9: =G10+G11+G12 -> 0 | H9: =H10+H11+H12 -> 0 | I9: =I10+I11+I12 -> 0 | ... N9: =N10+N11+N12 -> 0
A10: основные материалы | N10: =B10+C10+D10+E10+F10+G10+H10+I10+J10+K10+L10+M10 -> 0
A11: вспомогательные материалы | N11: =B11+C11+D11+E11+F11+G11+H11+I11+J11+K11+L11+M11 -> 0
A12: расходы на оборудование | N12: =B12+C12+D12+E12+F12+G12+H12+I12+J12+K12+L12+M12 -> 0
A13: Приобретение товаров для перепродажи | B13: =SUM(B14:B15) -> 0 | C13: =SUM(C14:C15) -> 0 | D13: =SUM(D14:D15) -> 0 | E13: =SUM(E14:E15) -> 0 | F13: =SUM(F14:F15) -> 0 | G13: =SUM(G14:G15) -> 0 | H13: =SUM(H14:H15) -> 0 | I13: =SUM(I14:I15) -> 0 | ... M13: =SUM(M14:M15) -> 0 | N13: =B13+C13+D13+E13+F13+G13+H13+I13+J13+K13+L13+M13 -> 0
A16: Содержание зданий | B16: =B17+B18+B19+B20 -> 0 | C16: =C17+C18+C19+C20 -> 0 | D16: =D17+D18+D19+D20 -> 0 | E16: =E17+E18+E19+E20 -> 0 | F16: =F17+F18+F19+F20 -> 0 | G16: =G17+G18+G19+G20 -> 0 | H16: =H17+H18+H19+H20 -> 0 | I16: =I17+I18+I19+I20 -> 0 | ... N16: =N17+N18+N19+N20 -> 0
A17: аренда | N17: =B17+C17+D17+E17+F17+G17+H17+I17+J17+K17+L17+M17 -> 0
A18: коммунальные расходы | N18: =B18+C18+D18+E18+F18+G18+H18+I18+J18+K18+L18+M18 -> 0
A19: охрана | N19: =B19+C19+D19+E19+F19+G19+H19+I19+J19+K19+L19+M19 -> 0
A20: ремонт помещений | N20: =B20+C20+D20+E20+F20+G20+H20+I20+J20+K20+L20+M20 -> 0
A21: Транспортные расходы | B21: =B22+B23+B24+B25 -> 0 | C21: =C22+C23+C24+C25 -> 0 | D21: =D22+D23+D24+D25 -> 0 | E21: =E22+E23+E24+E25 -> 0 | F21: =F22+F23+F24+F25 -> 0 | G21: =G22+G23+G24+G25 -> 0 | H21: =H22+H23+H24+H25 -> 0 | I21: =I22+I23+I24+I25 -> 0 | ... N21: =N22+N23+N24+N25 -> 0
A22: ГСМ | N22: =B22+C22+D22+E22+F22+G22+H22+I22+J22+K22+L22+M22 -> 0
A23: Ремонт и обслуживание транспорта | N23: =B23+C23+D23+E23+F23+G23+H23+I23+J23+K23+L23+M23 -> 0
A24: страхование а/м | N24: =B24+C24+D24+E24+F24+G24+H24+I24+J24+K24+L24+M24 -> 0
A25: прочие транспортные расходы | N25: =B25+C25+D25+E25+F25+G25+H25+I25+J25+K25+L25+M25 -> 0
A26: Реклама и продвижение | N26: =B26+C26+D26+E26+F26+G26+H26+I26+J26+K26+L26+M26 -> 0
A27: Услуги связи | B27: =B28+B29 -> 0 | C27: =C28+C29 -> 0 | D27: =D28+D29 -> 0 | E27: =E28+E29 -> 0 | F27: =F28+F29 -> 0 | G27: =G28+G29 -> 0 | H27: =H28+H29 -> 0 | I27: =I28+I29 -> 0 | ... M27: =M28+M29 -> 0 | N27: =B27+C27+D27+E27+F27+G27+H27+I27+J27+K27+L27+M27 -> 0
A28: телефон | N28: =B28+C28+D28+E28+F28+G28+H28+I28+J28+K28+L28+M28 -> 0
A29: интернет | N29: =B29+C29+D29+E29+F29+G29+H29+I29+J29+K29+L29+M29 -> 0
A30: Спецодежда | N30: =B30+C30+D30+E30+F30+G30+H30+I30+J30+K30+L30+M30 -> 0
A31: Расходы на персонал | B31: =B32+B33+B34 -> 0 | C31: =C32+C33+C34 -> 0 | D31: =D32+D33+D34 -> 0 | E31: =E32+E33+E34 -> 0 | F31: =F32+F33+F34 -> 0 | G31: =G32+G33+G34 -> 0 | H31: =H32+H33+H34 -> 0 | I31: =I32+I33+I34 -> 0 | ... M31: =M32+M33+M34 -> 0 | N31: =B31+C31+D31+E31+F31+G31+H31+I31+J31+K31+L31+M31 -> 0
A32: обучение сотрудников | N32: =B32+C32+D32+E32+F32+G32+H32+I32+J32+K32+L32+M32 -> 0
A33: подбор персонала | N33: =B33+C33+D33+E33+F33+G33+H33+I33+J33+K33+L33+M33 -> 0
A34: прочие расходы на персонал | N34: =B34+C34+D34+E34+F34+G34+H34+I34+J34+K34+L34+M34 -> 0
A35: Информационные и консультационные услуги | B35: =B36+B37+B39+B38 -> 0 | C35: =C36+C37+C39+C38 -> 0 | D35: =D36+D37+D39+D38 -> 0 | E35: =E36+E37+E39+E38 -> 0 | F35: =F36+F37+F39+F38 -> 0 | G35: =G36+G37+G39+G38 -> 0 | H35: =H36+H37+H39+H38 -> 0 | I35: =I36+I37+I39+I38 -> 0 | ... N35: =N36+N37+N39+N38 -> 0
A36: поддержка ПО | N36: =B36+C36+D36+E36+F36+G36+H36+I36+J36+K36+L36+M36 -> 0
A37: аутсорсинг | N37: =B37+C37+D37+E37+F37+G37+H37+I37+J37+K37+L37+M37 -> 0
A38: услуги ИП | N38: =B38+C38+D38+E38+F38+G38+H38+I38+J38+K38+L38+M38 -> 0
A39: прочие информационные услуги | N39: =B39+C39+D39+E39+F39+G39+H39+I39+J39+K39+L39+M39 -> 0
A40: Расходы офиса | B40: =B41+B42+B43 -> 0 | C40: =C41+C42+C43 -> 0 | D40: =D41+D42+D43 -> 0 | E40: =E41+E42+E43 -> 0 | F40: =F41+F42+F43 -> 0 | G40: =G41+G42+G43 -> 0 | H40: =H41+H42+H43 -> 0 | I40: =I41+I42+I43 -> 0 | ... M40: =M41+M42+M43 -> 0 | N40: =B40+C40+D40+E40+F40+G40+H40+I40+J40+K40+L40+M40 -> 0
A41: хозяйственные расходы | N41: =B41+C41+D41+E41+F41+G41+H41+I41+J41+K41+L41+M41 -> 0
A42: канцелярские товары | N42: =B42+C42+D42+E42+F42+G42+H42+I42+J42+K42+L42+M42 -> 0
...

Sheet Баланс
A1: Прогнозный баланс 2021
A2: Наименование статьи | B2: янв | C2: фев | D2: мар | E2: апр | F2: май | G2: июн | H2: июл | I2: авг | J2: сен | K2: окт | L2: ноя | M2: дек
A3: Активы | B3: =B4+B8 -> 0 | C3: =C4+C8 -> 0 | D3: =D4+D8 -> 0 | E3: =E4+E8 -> 0 | F3: =F4+F8 -> 0 | G3: =G4+G8 -> 0 | H3: =H4+H8 -> 0 | I3: =I4+I8 -> 0 | ... M3: =M4+M8 -> 0
A4: Внеоборотные активы | B4: =SUM(B5:B7) -> 0 | C4: =SUM(C5:C7) -> 0 | D4: =SUM(D5:D7) -> 0 | E4: =SUM(E5:E7) -> 0 | F4: =SUM(F5:F7) -> 0 | G4: =SUM(G5:G7) -> 0 | H4: =SUM(H5:H7) -> 0 | I4: =SUM(I5:I7) -> 0 | ... M4: =SUM(M5:M7) -> 0
A5: Производственное оборудование
A6: Транспорт
A7: Мебель
A8: Оборотные активы | B8: =SUM(B9:B13) -> 0 | C8: =SUM(C9:C13) -> 0 | D8: =SUM(D9:D13) -> 0 | E8: =SUM(E9:E13) -> 0 | F8: =SUM(F9:F13) -> 0 | G8: =SUM(G9:G13) -> 0 | H8: =SUM(H9:H13) -> 0 | I8: =SUM(I9:I13) -> 0 | ... M8: =SUM(M9:M13) -> 0
A9: Запасы материалов
A10: Запасы готовой продукции
A11: Денежные средства
A12: Дебиторская задолженность
A13: Прочие оборотные активы
A14: Пассивы | B14: =B15+B20+B24 -> 0 | C14: =C15+C20+C24 -> 0 | D14: =D15+D20+D24 -> 0 | E14: =E15+E20+E24 -> 0 | F14: =F15+F20+F24 -> 0 | G14: =G15+G20+G24 -> 0 | H14: =H15+H20+H24 -> 0 | I14: =I15+I20+I24 -> 0 | ... M14: =M15+M20+M24 -> 0
A15: Собственный капитал | B15: =SUM(B16:B19) -> 0 | C15: =SUM(C16:C19) -> 0 | D15: =SUM(D16:D19) -> 0 | E15: =SUM(E16:E19) -> 0 | F15: =SUM(F16:F19) -> 0 | G15: =SUM(G16:G19) -> 0 | H15: =SUM(H16:H19) -> 0 | I15: =SUM(I16:I19) -> 0 | ... M15: =SUM(M16:M19) -> 0
A16: Уставный капитал
A17: Добавочный капитал
A18: Резервный капитал
A19: Нераспределенная прибыль
A20: Долгосрочные обязательства | B20: =SUM(B21:B23) -> 0 | C20: =SUM(C21:C23) -> 0 | D20: =SUM(D21:D23) -> 0 | E20: =SUM(E21:E23) -> 0 | F20: =SUM(F21:F23) -> 0 | G20: =SUM(G21:G23) -> 0 | H20: =SUM(H21:H23) -> 0 | I20: =SUM(I21:I23) -> 0 | ... M20: =SUM(M21:M23) -> 0
A21: Задолженность по кредитам и займам
A24: Краткосрчные обязательства | B24: =SUM(B25:B29) -> 0 | C24: =SUM(C25:C29) -> 0 | D24: =SUM(D25:D29) -> 0 | E24: =SUM(E25:E29) -> 0 | F24: =SUM(F25:F29) -> 0 | G24: =SUM(G25:G29) -> 0 | H24: =SUM(H25:H29) -> 0 | I24: =SUM(I25:I29) -> 0 | ... M24: =SUM(M25:M29) -> 0
A25: Кредиторская задолженность перед поставщиками
A26: Кредиторская задолженность перед покупателями
A27: Кредиторская задолженность перед сотрудниками
A28: Кредиторская задолженность по налогам и взносам
A30: контроль | B30: =IF(B3=B14,"","ОШИБКА") | C30: =IF(C3=C14,"","ОШИБКА") | D30: =IF(D3=D14,"","ОШИБКА") | E30: =IF(E3=E14,"","ОШИБКА") | F30: =IF(F3=F14,"","ОШИБКА") | G30: =IF(G3=G14,"","ОШИБКА") | H30: =IF(H3=H14,"","ОШИБКА") | I30: =IF(I3=I14,"","ОШИБКА") | ... M30: =IF(M3=M14,"","ОШИБКА")

Sheet ОПиУ
A1: Прогнозный отчет о прибылях и убытках 2021 г.
A2: Наименование статьи | B2: янв | C2: фев | D2: мар | E2: апр | F2: май | G2: июн | H2: июл | I2: авг | J2: сен | K2: окт | L2: ноя | M2: дек | N2: ГОД
A3: Доход | B3: =B4 | C3: =C4 | D3: =D4 | E3: =E4 | F3: =F4 | G3: =G4 | H3: =H4 | I3: =I4 | ... N3: =N4 -> 0
A4: Доход от продаж | N4: =B4+C4+D4+E4+F4+G4+H4+I4+J4+K4+L4+M4 -> 0
A5: Расход | B5: =B6+B9+B26+B30+B31+B34+B44+B43 -> 0 | C5: =C6+C9+C26+C30+C31+C34+C44+C43 -> 0 | D5: =D6+D9+D26+D30+D31+D34+D44+D43 -> 0 | E5: =E6+E9+E26+E30+E31+E34+E44+E43 -> 0 | F5: =F6+F9+F26+F30+F31+F34+F44+F43 -> 0 | G5: =G6+G9+G26+G30+G31+G34+G44+G43 -> 0 | H5: =H6+H9+H26+H30+H31+H34+H44+H43 -> 0 | I5: =I6+I9+I26+I30+I31+I34+I44+I43 -> 0 | ... N5: =N6+N9+N26+N30+N31+N34+N44+N43 -> 0
A6: Материальные расходы | B6: =SUM(B7:B8) -> 0 | C6: =SUM(C7:C8) -> 0 | D6: =SUM(D7:D8) -> 0 | E6: =SUM(E7:E8) -> 0 | F6: =SUM(F7:F8) -> 0 | G6: =SUM(G7:G8) -> 0 | H6: =SUM(H7:H8) -> 0 | I6: =SUM(I7:I8) -> 0 | ... M6: =SUM(M7:M8) -> 0 | N6: =B6+C6+D6+E6+F6+G6+H6+I6+J6+K6+L6+M6 -> 0
A7: сырье | N7: =B7+C7+D7+E7+F7+G7+H7+I7+J7+K7+L7+M7 -> 0
A8: основные материалы | N8: =B8+C8+D8+E8+F8+G8+H8+I8+J8+K8+L8+M8 -> 0
A9: Приобретение товаров для перепродажи | B9: =SUM(B10:B11) -> 0 | C9: =SUM(C10:C11) -> 0 | D9: =SUM(D10:D11) -> 0 | E9: =SUM(E10:E11) -> 0 | F9: =SUM(F10:F11) -> 0 | G9: =SUM(G10:G11) -> 0 | H9: =SUM(H10:H11) -> 0 | I9: =SUM(I10:I11) -> 0 | ... M9: =SUM(M10:M11) -> 0 | N9: =B9+C9+D9+E9+F9+G9+H9+I9+J9+K9+L9+M9 -> 0
N10: =B10+C10+D10+E10+F10+G10+H10+I10+J10+K10+L10+M10 -> 0
N11: =B11+C11+D11+E11+F11+G11+H11+I11+J11+K11+L11+M11 -> 0
A12: Маржинальная прибыль | B12: =B3-B6-B9 -> 0 | C12: =C3-C6-C9 -> 0 | D12: =D3-D6-D9 -> 0 | E12: =E3-E6-E9 -> 0 | F12: =F3-F6-F9 -> 0 | G12: =G3-G6-G9 -> 0 | H12: =H3-H6-H9 -> 0 | I12: =I3-I6-I9 -> 0 | ... N12: =N3-N6-N9 -> 0
A13: рентабельность маржинальной прибыли, % | B13: =IFERROR(B12/B3,) | C13: =IFERROR(C12/C3,) | D13: =IFERROR(D12/D3,) | E13: =IFERROR(E12/E3,) | F13: =IFERROR(F12/F3,) | G13: =IFERROR(G12/G3,) | H13: =IFERROR(H12/H3,) | I13: =IFERROR(I12/I3,) | ... N13: =IFERROR(N12/N3,)
A14: Общепроизводственные расходы
A15: Расходы на оплату труда
A16: Содержание зданий
A17: Транспортные расходы
A18: Расходы на содержание оборудования
A19: Расходы на персонал
A20: Прочие производственые расходы расходы
A21: Спецодежда
A22: Валовая прибыль | B22: =B13-B16-B19 -> 0 | C22: =C13-C16-C19 -> 0 | D22: =D13-D16-D19 -> 0 | E22: =E13-E16-E19 -> 0 | F22: =F13-F16-F19 -> 0 | G22: =G13-G16-G19 -> 0 | H22: =H13-H16-H19 -> 0 | I22: =I13-I16-I19 -> 0 | ... N22: =N13-N16-N19 -> 0
A23: рентабельность валовой прибыли, % | B23: =IFERROR(B22/B13,) | C23: =IFERROR(C22/C13,) | D23: =IFERROR(D22/D13,) | E23: =IFERROR(E22/E13,) | F23: =IFERROR(F22/F13,) | G23: =IFERROR(G22/G13,) | H23: =IFERROR(H22/H13,) | I23: =IFERROR(I22/I13,) | ... N23: =IFERROR(N22/N13,)
A24: Административные расходы | B24: =SUM(B25:B34) -> 0 | C24: =SUM(C25:C34) -> 0 | D24: =SUM(D25:D34) -> 0 | E24: =SUM(E25:E34) -> 0 | F24: =SUM(F25:F34) -> 0 | G24: =SUM(G25:G34) -> 0 | H24: =SUM(H25:H34) -> 0 | I24: =SUM(I25:I34) -> 0 | ... N24: =SUM(N25:N34) -> 0
A25: Расходы на оплату труда | B25: ='БДР-свод_БЕЗ НДС'!B50 -> 0 | C25: ='БДР-свод_БЕЗ НДС'!C50 -> 0 | D25: ='БДР-свод_БЕЗ НДС'!D50 -> 0 | E25: ='БДР-свод_БЕЗ НДС'!E50 -> 0 | F25: ='БДР-свод_БЕЗ НДС'!F50 -> 0 | G25: ='БДР-свод_БЕЗ НДС'!G50 -> 0 | H25: ='БДР-свод_БЕЗ НДС'!H50 -> 0 | I25: ='БДР-свод_БЕЗ НДС'!I50 -> 0 | ... M25: ='БДР-свод_БЕЗ НДС'!M50 -> 0
A26: Содержание зданий | B26: ='БДР-свод_БЕЗ НДС'!B54 -> 0 | C26: ='БДР-свод_БЕЗ НДС'!C54 -> 0 | D26: ='БДР-свод_БЕЗ НДС'!D54 -> 0 | E26: ='БДР-свод_БЕЗ НДС'!E54 -> 0 | F26: ='БДР-свод_БЕЗ НДС'!F54 -> 0 | G26: ='БДР-свод_БЕЗ НДС'!G54 -> 0 | H26: ='БДР-свод_БЕЗ НДС'!H54 -> 0 | I26: ='БДР-свод_БЕЗ НДС'!I54 -> 0 | ... M26: ='БДР-свод_БЕЗ НДС'!M54 -> 0 | N26: =B26+C26+D26+E26+F26+G26+H26+I26+J26+K26+L26+M26 -> 0
A27: Услуги связи | B27: ='БДР-свод_БЕЗ НДС'!B59 -> 0 | C27: ='БДР-свод_БЕЗ НДС'!C59 -> 0 | D27: ='БДР-свод_БЕЗ НДС'!D59 -> 0 | E27: ='БДР-свод_БЕЗ НДС'!E59 -> 0 | F27: ='БДР-свод_БЕЗ НДС'!F59 -> 0 | G27: ='БДР-свод_БЕЗ НДС'!G59 -> 0 | H27: ='БДР-свод_БЕЗ НДС'!H59 -> 0 | I27: ='БДР-свод_БЕЗ НДС'!I59 -> 0 | ... M27: ='БДР-свод_БЕЗ НДС'!M59 -> 0 | N27: =B27+C27+D27+E27+F27+G27+H27+I27+J27+K27+L27+M27 -> 0
A28: Расходы на персонал | B28: ='БДР-свод_БЕЗ НДС'!B62 -> 0 | C28: ='БДР-свод_БЕЗ НДС'!C62 -> 0 | D28: ='БДР-свод_БЕЗ НДС'!D62 -> 0 | E28: ='БДР-свод_БЕЗ НДС'!E62 -> 0 | F28: ='БДР-свод_БЕЗ НДС'!F62 -> 0 | G28: ='БДР-свод_БЕЗ НДС'!G62 -> 0 | H28: ='БДР-свод_БЕЗ НДС'!H62 -> 0 | I28: ='БДР-свод_БЕЗ НДС'!I62 -> 0 | ... M28: ='БДР-свод_БЕЗ НДС'!M62 -> 0 | N28: =B28+C28+D28+E28+F28+G28+H28+I28+J28+K28+L28+M28 -> 0
A29: Расходы офиса | B29: ='БДР-свод_БЕЗ НДС'!B66 -> 0 | C29: ='БДР-свод_БЕЗ НДС'!C66 -> 0 | D29: ='БДР-свод_БЕЗ НДС'!D66 -> 0 | E29: ='БДР-свод_БЕЗ НДС'!E66 -> 0 | F29: ='БДР-свод_БЕЗ НДС'!F66 -> 0 | G29: ='БДР-свод_БЕЗ НДС'!G66 -> 0 | H29: ='БДР-свод_БЕЗ НДС'!H66 -> 0 | I29: ='БДР-свод_БЕЗ НДС'!I66 -> 0 | ... M29: ='БДР-свод_БЕЗ НДС'!M66 -> 0 | N29: =B29+C29+D29+E29+F29+G29+H29+I29+J29+K29+L29+M29 -> 0
A30: Информац. и консультац. услуги | B30: ='БДР-свод_БЕЗ НДС'!B70 -> 0 | C30: ='БДР-свод_БЕЗ НДС'!C70 -> 0 | D30: ='БДР-свод_БЕЗ НДС'!D70 -> 0 | E30: ='БДР-свод_БЕЗ НДС'!E70 -> 0 | F30: ='БДР-свод_БЕЗ НДС'!F70 -> 0 | G30: ='БДР-свод_БЕЗ НДС'!G70 -> 0 | H30: ='БДР-свод_БЕЗ НДС'!H70 -> 0 | I30: ='БДР-свод_БЕЗ НДС'!I70 -> 0 | ... M30: ='БДР-свод_БЕЗ НДС'!M70 -> 0 | N30: =N3*3% -> 0
A31: Расходы на денежное обращение | B31: ='БДР-свод_БЕЗ НДС'!B74 -> 0 | C31: ='БДР-свод_БЕЗ НДС'!C74 -> 0 | D31: ='БДР-свод_БЕЗ НДС'!D74 -> 0 | E31: ='БДР-свод_БЕЗ НДС'!E74 -> 0 | F31: ='БДР-свод_БЕЗ НДС'!F74 -> 0 | G31: ='БДР-свод_БЕЗ НДС'!G74 -> 0 | H31: ='БДР-свод_БЕЗ НДС'!H74 -> 0 | I31: ='БДР-свод_БЕЗ НДС'!I74 -> 0 | ... M31: ='БДР-свод_БЕЗ НДС'!M74 -> 0 | N31: =B31+C31+D31+E31+F31+G31+H31+I31+J31+K31+L31+M31 -> 0
A32: Прочие административные расходы | B32: ='БДР-свод_БЕЗ НДС'!B78 -> 0 | C32: ='БДР-свод_БЕЗ НДС'!C78 -> 0 | D32: ='БДР-свод_БЕЗ НДС'!D78 -> 0 | E32: ='БДР-свод_БЕЗ НДС'!E78 -> 0 | F32: ='БДР-свод_БЕЗ НДС'!F78 -> 0 | G32: ='БДР-свод_БЕЗ НДС'!G78 -> 0 | H32: ='БДР-свод_БЕЗ НДС'!H78 -> 0 | I32: ='БДР-свод_БЕЗ НДС'!I78 -> 0 | ... M32: ='БДР-свод_БЕЗ НДС'!M78 -> 0 | N32: =B32+C32+D32+E32+F32+G32+H32+I32+J32+K32+L32+M32 -> 0
A33: Спецодежда | B33: ='БДР-свод_БЕЗ НДС'!B83 | C33: ='БДР-свод_БЕЗ НДС'!C83 | D33: ='БДР-свод_БЕЗ НДС'!D83 | E33: ='БДР-свод_БЕЗ НДС'!E83 | F33: ='БДР-свод_БЕЗ НДС'!F83 | G33: ='БДР-свод_БЕЗ НДС'!G83 | H33: ='БДР-свод_БЕЗ НДС'!H83 | I33: ='БДР-свод_БЕЗ НДС'!I83 | ... M33: ='БДР-свод_БЕЗ НДС'!M83 | N33: =B33+C33+D33+E33+F33+G33+H33+I33+J33+K33+L33+M33 -> 0
A34: Налоги по операционной деятельности | B34: ='БДР-свод_БЕЗ НДС'!B87 -> 0 | C34: ='БДР-свод_БЕЗ НДС'!C87 -> 0 | D34: ='БДР-свод_БЕЗ НДС'!D87 -> 0 | E34: ='БДР-свод_БЕЗ НДС'!E87 -> 0 | F34: ='БДР-свод_БЕЗ НДС'!F87 -> 0 | G34: ='БДР-свод_БЕЗ НДС'!G87 -> 0 | H34: ='БДР-свод_БЕЗ НДС'!H87 -> 0 | I34: ='БДР-свод_БЕЗ НДС'!I87 -> 0 | ... M34: ='БДР-свод_БЕЗ НДС'!M87 -> 0 | N34: =B34+C34+D34+E34+F34+G34+H34+I34+J34+K34+L34+M34 -> 0
A35: Коммерческие расходы | B35: =SUM(B36:B37) -> 0 | C35: =SUM(C36:C37) -> 0 | D35: =SUM(D36:D37) -> 0 | E35: =SUM(E36:E37) -> 0 | F35: =SUM(F36:F37) -> 0 | G35: =SUM(G36:G37) -> 0 | H35: =SUM(H36:H37) -> 0 | I35: =SUM(I36:I37) -> 0 | ... N35: =SUM(N36:N37) -> 0
A36: Расходы на оплату труда | B36: ='БДР-свод_БЕЗ НДС'!B41 -> 0 | C36: ='БДР-свод_БЕЗ НДС'!C41 -> 0 | D36: ='БДР-свод_БЕЗ НДС'!D41 -> 0 | E36: ='БДР-свод_БЕЗ НДС'!E41 -> 0 | F36: ='БДР-свод_БЕЗ НДС'!F41 -> 0 | G36: ='БДР-свод_БЕЗ НДС'!G41 -> 0 | H36: ='БДР-свод_БЕЗ НДС'!H41 -> 0 | I36: ='БДР-свод_БЕЗ НДС'!I41 -> 0 | ... N36: ='БДР-свод_БЕЗ НДС'!N41 -> 0
A37: Реклама и продвижение | B37: ='БДР-свод_БЕЗ НДС'!B45 -> 0 | C37: ='БДР-свод_БЕЗ НДС'!C45 -> 0 | D37: ='БДР-свод_БЕЗ НДС'!D45 -> 0 | E37: ='БДР-свод_БЕЗ НДС'!E45 -> 0 | F37: ='БДР-свод_БЕЗ НДС'!F45 -> 0 | G37: ='БДР-свод_БЕЗ НДС'!G45 -> 0 | H37: ='БДР-свод_БЕЗ НДС'!H45 -> 0 | I37: ='БДР-свод_БЕЗ НДС'!I45 -> 0 | ... N37: ='БДР-свод_БЕЗ НДС'!N45 -> 0
A38: Операционная прибыль | B38: =B22-B24-B35 -> 0 | C38: =C22-C24-C35 -> 0 | D38: =D22-D24-D35 -> 0 | E38: =E22-E24-E35 -> 0 | F38: =F22-F24-F35 -> 0 | G38: =G22-G24-G35 -> 0 | H38: =H22-H24-H35 -> 0 | I38: =I22-I24-I35 -> 0 | ... N38: =N22-N24-N35 -> 0
A39: рентабельность продаж, % | B39: =IFERROR(B38/B3,"") | C39: =IFERROR(C38/C3,"") | D39: =IFERROR(D38/D3,"") | E39: =IFERROR(E38/E3,"") | F39: =IFERROR(F38/F3,"") | G39: =IFERROR(G38/G3,"") | H39: =IFERROR(H38/H3,"") | I39: =IFERROR(I38/I3,"") | ... N39: =IFERROR(N38/N3,"")
A40: Доход от финансовой деятельности | N40: =B40+C40+D40+E40+F40+G40+H40+I40+J40+K40+L40+M40 -> 0
...

Sheet БДР-свод_БЕЗ НДС
A1: Бюджет доходов и расходов 2021 г.
A2: Наименование статьи | B2: янв | C2: фев | D2: мар | E2: апр | F2: май | G2: июн | H2: июл | I2: авг | J2: сен | K2: окт | L2: ноя | M2: дек | N2: ГОД
A3: Доходы от операционной деятельности | B3: =B4 | C3: =C4 | D3: =D4 | E3: =E4 | F3: =F4 | G3: =G4 | H3: =H4 | I3: =I4 | ... M3: =M4 | N3: =B3+C3+D3+E3+F3+G3+H3+I3+J3+K3+L3+M3 -> 0
A4: Доход от продажи воды | N4: =B4+C4+D4+E4+F4+G4+H4+I4+J4+K4+L4+M4 -> 0
A5: Расходы по операционной деятельности | B5: =B6+B40+B87+B49 -> 0 | C5: =C6+C40+C87+C49 -> 0 | D5: =D6+D40+D87+D49 -> 0 | E5: =E6+E40+E87+E49 -> 0 | F5: =F6+F40+F87+F49 -> 0 | G5: =G6+G40+G87+G49 -> 0 | H5: =H6+H40+H87+H49 -> 0 | I5: =I6+I40+I87+I49 -> 0 | ... N5: =N6+N40+N87+N49 -> 0
A6: Расходы по продаже | B6: =B7 -> 0 | C6: =C7 -> 0 | D6: =D7 -> 0 | E6: =E7 -> 0 | F6: =F7 -> 0 | G6: =G7 -> 0 | H6: =H7 -> 0 | I6: =I7 -> 0 | ... M6: =M7 -> 0 | N6: =B6+C6+D6+E6+F6+G6+H6+I6+J6+K6+L6+M6 -> 0
A7: Производственная себестоимость продукции | B7: =B8+B11+B15+B20+B24+B27+B31+B36+B37 -> 0 | C7: =C8+C11+C15+C20+C24+C27+C31+C36+C37 -> 0 | D7: =D8+D11+D15+D20+D24+D27+D31+D36+D37 -> 0 | E7: =E8+E11+E15+E20+E24+E27+E31+E36+E37 -> 0 | F7: =F8+F11+F15+F20+F24+F27+F31+F36+F37 -> 0 | G7: =G8+G11+G15+G20+G24+G27+G31+G36+G37 -> 0 | H7: =H8+H11+H15+H20+H24+H27+H31+H36+H37 -> 0 | I7: =I8+I11+I15+I20+I24+I27+I31+I36+I37 -> 0 | ... N7: =N8+N11+N15+N20+N24+N27+N31+N36+N37 -> 0
A8: Материальные расходы | B8: =B9+B10 -> 0 | C8: =C9+C10 -> 0 | D8: =D9+D10 -> 0 | E8: =E9+E10 -> 0 | F8: =F9+F10 -> 0 | G8: =G9+G10 -> 0 | H8: =H9+H10 -> 0 | I8: =I9+I10 -> 0 | ... N8: =N9+N10 -> 0
A9: основные материалы | B9: ='Бюджет производственных расходо'!B5 | C9: ='Бюджет производственных расходо'!C5 | D9: ='Бюджет производственных расходо'!D5 | E9: ='Бюджет производственных расходо'!E5 | F9: ='Бюджет производственных расходо'!F5 | G9: ='Бюджет производственных расходо'!G5 | H9: ='Бюджет производственных расходо'!H5 | I9: ='Бюджет производственных расходо'!I5 | ... M9: ='Бюджет производственных расходо'!M5 | N9: =B9+C9+D9+E9+F9+G9+H9+I9+J9+K9+L9+M9 -> 0
A10: вспомогательные материалы | B10: ='Бюджет производственных расходо'!B6 | C10: ='Бюджет производственных расходо'!C6 | D10: ='Бюджет производственных расходо'!D6 | E10: ='Бюджет производственных расходо'!E6 | F10: ='Бюджет производственных расходо'!F6 | G10: ='Бюджет производственных расходо'!G6 | H10: ='Бюджет производственных расходо'!H6 | I10: ='Бюджет производственных расходо'!I6 | ... M10: ='Бюджет производственных расходо'!M6 | N10: =B10+C10+D10+E10+F10+G10+H10+I10+J10+K10+L10+M10 -> 0
A11: Расходы на оплату труда | B11: =SUM(B12:B14) -> 0 | C11: =SUM(C12:C14) -> 0 | D11: =SUM(D12:D14) -> 0 | E11: =SUM(E12:E14) -> 0 | F11: =SUM(F12:F14) -> 0 | G11: =SUM(G12:G14) -> 0 | H11: =SUM(H12:H14) -> 0 | I11: =SUM(I12:I14) -> 0 | ... M11: =SUM(M12:M14) -> 0 | N11: =B11+C11+D11+E11+F11+G11+H11+I11+J11+K11+L11+M11 -> 0
A12: заработная плата | N12: =B12+C12+D12+E12+F12+G12+H12+I12+J12+K12+L12+M12 -> 0
A13: отчисления с ФОТ | N13: =B13+C13+D13+E13+F13+G13+H13+I13+J13+K13+L13+M13 -> 0
A14: НДФЛ | N14: =B14+C14+D14+E14+F14+G14+H14+I14+J14+K14+L14+M14 -> 0
A15: Содержание зданий | B15: =B16+B20+B21+B22 -> 0 | C15: =C16+C20+C21+C22 -> 0 | D15: =D16+D20+D21+D22 -> 0 | E15: =E16+E20+E21+E22 -> 0 | F15: =F16+F20+F21+F22 -> 0 | G15: =G16+G20+G21+G22 -> 0 | H15: =H16+H20+H21+H22 -> 0 | I15: =I16+I20+I21+I22 -> 0 | ... M15: =M16+M20+M21+M22 -> 0 | N15: =B15+C15+D15+E15+F15+G15+H15+I15+J15+K15+L15+M15 -> 0
A16: Аренда | B16: ='Бюджет производственных расходо'!B9 -> 0 | C16: ='Бюджет производственных расходо'!C9 -> 0 | D16: ='Бюджет производственных расходо'!D9 -> 0 | E16: ='Бюджет производственных расходо'!E9 -> 0 | F16: ='Бюджет производственных расходо'!F9 -> 0 | G16: ='Бюджет производственных расходо'!G9 -> 0 | H16: ='Бюджет производственных расходо'!H9 -> 0 | I16: ='Бюджет производственных расходо'!I9 -> 0 | ... M16: ='Бюджет производственных расходо'!M9 -> 0 | N16: =N17 -> 0
A17: Коммунальные расходы | B17: ='Бюджет производственных расходо'!B13 | C17: ='Бюджет производственных расходо'!C13 | D17: ='Бюджет производственных расходо'!D13 | E17: ='Бюджет производственных расходо'!E13 | F17: ='Бюджет производственных расходо'!F13 | G17: ='Бюджет производственных расходо'!G13 | H17: ='Бюджет производственных расходо'!H13 | I17: ='Бюджет производственных расходо'!I13 | ... M17: ='Бюджет производственных расходо'!M13 | N17: =B17+C17+D17+E17+F17+G17+H17+I17+J17+K17+L17+M17 -> 0
A18: Охрана помещений | B18: ='Бюджет производственных расходо'!B14 | C18: ='Бюджет производственных расходо'!C14 | D18: ='Бюджет производственных расходо'!D14 | E18: ='Бюджет производственных расходо'!E14 | F18: ='Бюджет производственных расходо'!F14 | G18: ='Бюджет производственных расходо'!G14 | H18: ='Бюджет производственных расходо'!H14 | I18: ='Бюджет производственных расходо'!I14 | ... M18: ='Бюджет производственных расходо'!M14 | N18: =B18+C18+D18+E18+F18+G18+H18+I18+J18+K18+L18+M18 -> 0
A19: Ремонт помещений | B19: ='Бюджет производственных расходо'!B15 | C19: ='Бюджет производственных расходо'!C15 | D19: ='Бюджет производственных расходо'!D15 | E19: ='Бюджет производственных расходо'!E15 | F19: ='Бюджет производственных расходо'!F15 | G19: ='Бюджет производственных расходо'!G15 | H19: ='Бюджет производственных расходо'!H15 | I19: ='Бюджет производственных расходо'!I15 | ... M19: ='Бюджет производственных расходо'!M15 | N19: =B19+C19+D19+E19+F19+G19+H19+I19+J19+K19+L19+M19 -> 0
A20: Транспортные расходы | B20: =B21+B23 -> 0 | C20: =C21+C23 -> 0 | D20: =D21+D23 -> 0 | E20: =E21+E23 -> 0 | F20: =F21+F23 -> 0 | G20: =G21+G23 -> 0 | H20: =H21+H23 -> 0 | I20: =I21+I23 -> 0 | ... M20: =M21+M23 -> 0 | N20: =B20+C20+D20+E20+F20+G20+H20+I20+J20+K20+L20+M20 -> 0
A21: ГСМ | B21: ='Бюджет производственных расходо'!B17 | C21: ='Бюджет производственных расходо'!C17 | D21: ='Бюджет производственных расходо'!D17 | E21: ='Бюджет производственных расходо'!E17 | F21: ='Бюджет производственных расходо'!F17 | G21: ='Бюджет производственных расходо'!G17 | H21: ='Бюджет производственных расходо'!H17 | I21: ='Бюджет производственных расходо'!I17 | ... M21: ='Бюджет производственных расходо'!M17 | N21: =B21+C21+D21+E21+F21+G21+H21+I21+J21+K21+L21+M21 -> 0
A22: Содержание транспорта | B22: ='Бюджет производственных расходо'!B18 | C22: ='Бюджет производственных расходо'!C18 | D22: ='Бюджет производственных расходо'!D18 | E22: ='Бюджет производственных расходо'!E18 | F22: ='Бюджет производственных расходо'!F18 | G22: ='Бюджет производственных расходо'!G18 | H22: ='Бюджет производственных расходо'!H18 | I22: ='Бюджет производственных расходо'!I18 | ... M22: ='Бюджет производственных расходо'!M18
A23: Прочие транспортные расходы | B23: ='Бюджет производственных расходо'!B19 | C23: ='Бюджет производственных расходо'!C19 | D23: ='Бюджет производственных расходо'!D19 | E23: ='Бюджет производственных расходо'!E19 | F23: ='Бюджет производственных расходо'!F19 | G23: ='Бюджет производственных расходо'!G19 | H23: ='Бюджет производственных расходо'!H19 | I23: ='Бюджет производственных расходо'!I19 | ... M23: ='Бюджет производственных расходо'!M19 | N23: =B23+C23+D23+E23+F23+G23+H23+I23+J23+K23+L23+M23 -> 0
A24: Расходы на содержание оборудования | B24: =B25+B26 -> 0 | C24: =C25+C26 -> 0 | D24: =D25+D26 -> 0 | E24: =E25+E26 -> 0 | F24: =F25+F26 -> 0 | G24: =G25+G26 -> 0 | H24: =H25+H26 -> 0 | I24: =I25+I26 -> 0 | ... N24: =N25+N26 -> 0
A25: Обслуживание оборудования | B25: ='Бюджет производственных расходо'!B21 | C25: ='Бюджет производственных расходо'!C21 | D25: ='Бюджет производственных расходо'!D21 | E25: ='Бюджет производственных расходо'!E21 | F25: ='Бюджет производственных расходо'!F21 | G25: ='Бюджет производственных расходо'!G21 | H25: ='Бюджет производственных расходо'!H21 | I25: ='Бюджет производственных расходо'!I21 | ... M25: ='Бюджет производственных расходо'!M21 | N25: =B25+C25+D25+E25+F25+G25+H25+I25+J25+K25+L25+M25 -> 0
A26: Ремонт оборудования | B26: ='Бюджет производственных расходо'!B22 | C26: ='Бюджет производственных расходо'!C22 | D26: ='Бюджет производственных расходо'!D22 | E26: ='Бюджет производственных расходо'!E22 | F26: ='Бюджет производственных расходо'!F22 | G26: ='Бюджет производственных расходо'!G22 | H26: ='Бюджет производственных расходо'!H22 | I26: ='Бюджет производственных расходо'!I22 | ... M26: ='Бюджет производственных расходо'!M22 | N26: =B26+C26+D26+E26+F26+G26+H26+I26+J26+K26+L26+M26 -> 0
A27: Расходы на персонал | B27: =SUM(B28:B30) -> 0 | C27: =SUM(C28:C30) -> 0 | D27: =SUM(D28:D30) -> 0 | E27: =SUM(E28:E30) -> 0 | F27: =SUM(F28:F30) -> 0 | G27: =SUM(G28:G30) -> 0 | H27: =SUM(H28:H30) -> 0 | I27: =SUM(I28:I30) -> 0 | ... N27: =SUM(N28:N30) -> 0
A28: обучение сотрудников | B28: ='Бюджет производственных расходо'!B24 | C28: ='Бюджет производственных расходо'!C24 | D28: ='Бюджет производственных расходо'!D24 | E28: ='Бюджет производственных расходо'!E24 | F28: ='Бюджет производственных расходо'!F24 | G28: ='Бюджет производственных расходо'!G24 | H28: ='Бюджет производственных расходо'!H24 | I28: ='Бюджет производственных расходо'!I24 | ... M28: ='Бюджет производственных расходо'!M24
A29: подбор персонала | B29: ='Бюджет производственных расходо'!B25 | C29: ='Бюджет производственных расходо'!C25 | D29: ='Бюджет производственных расходо'!D25 | E29: ='Бюджет производственных расходо'!E25 | F29: ='Бюджет производственных расходо'!F25 | G29: ='Бюджет производственных расходо'!G25 | H29: ='Бюджет производственных расходо'!H25 | I29: ='Бюджет производственных расходо'!I25 | ... M29: ='Бюджет производственных расходо'!M25
A30: прочие расходы на персонал | B30: ='Бюджет производственных расходо'!B26 | C30: ='Бюджет производственных расходо'!C26 | D30: ='Бюджет производственных расходо'!D26 | E30: ='Бюджет производственных расходо'!E26 | F30: ='Бюджет производственных расходо'!F26 | G30: ='Бюджет производственных расходо'!G26 | H30: ='Бюджет производственных расходо'!H26 | I30: ='Бюджет производственных расходо'!I26 | ... M30: ='Бюджет производственных расходо'!M26
A31: Прочие производственые расходы расходы | B31: =B32+B33+B34+B35 -> 0 | C31: =C32+C33+C34+C35 -> 0 | D31: =D32+D33+D34+D35 -> 0 | E31: =E32+E33+E34+E35 -> 0 | F31: =F32+F33+F34+F35 -> 0 | G31: =G32+G33+G34+G35 -> 0 | H31: =H32+H33+H34+H35 -> 0 | I31: =I32+I33+I34+I35 -> 0 | ... M31: =M32+M33+M34+M35 -> 0 | N31: =B31+C31+D31+E31+F31+G31+H31+I31+J31+K31+L31+M31 -> 0
B32: ='Бюджет производственных расходо'!B28 | C32: ='Бюджет производственных расходо'!C28 | D32: ='Бюджет производственных расходо'!D28 | E32: ='Бюджет производственных расходо'!E28 | F32: ='Бюджет производственных расходо'!F28 | G32: ='Бюджет производственных расходо'!G28 | H32: ='Бюджет производственных расходо'!H28 | I32: ='Бюджет производственных расходо'!I28 | ... M32: ='Бюджет производственных расходо'!M28
B33: ='Бюджет производственных расходо'!B29 | C33: ='Бюджет производственных расходо'!C29 | D33: ='Бюджет производственных расходо'!D29 | E33: ='Бюджет производственных расходо'!E29 | F33: ='Бюджет производственных расходо'!F29 | G33: ='Бюджет производственных расходо'!G29 | H33: ='Бюджет производственных расходо'!H29 | I33: ='Бюджет производственных расходо'!I29 | ... M33: ='Бюджет производственных расходо'!M29
B34: ='Бюджет производственных расходо'!B30 | C34: ='Бюджет производственных расходо'!C30 | D34: ='Бюджет производственных расходо'!D30 | E34: ='Бюджет производственных расходо'!E30 | F34: ='Бюджет производственных расходо'!F30 | G34: ='Бюджет производственных расходо'!G30 | H34: ='Бюджет производственных расходо'!H30 | I34: ='Бюджет производственных расходо'!I30 | ... M34: ='Бюджет производственных расходо'!M30
B35: ='Бюджет производственных расходо'!B31 | C35: ='Бюджет производственных расходо'!C31 | D35: ='Бюджет производственных расходо'!D31 | E35: ='Бюджет производственных расходо'!E31 | F35: ='Бюджет производственных расходо'!F31 | G35: ='Бюджет производственных расходо'!G31 | H35: ='Бюджет производственных расходо'!H31 | I35: ='Бюджет производственных расходо'!I31 | ... M35: ='Бюджет производственных расходо'!M31
A36: Спецодежда | B36: ='Бюджет производственных расходо'!B32 | C36: ='Бюджет производственных расходо'!C32 | D36: ='Бюджет производственных расходо'!D32 | E36: ='Бюджет производственных расходо'!E32 | F36: ='Бюджет производственных расходо'!F32 | G36: ='Бюджет производственных расходо'!G32 | H36: ='Бюджет производственных расходо'!H32 | I36: ='Бюджет производственных расходо'!I32 | ... M36: ='Бюджет производственных расходо'!M32
A37: Амортизация ОС и НМА | B37: ='Бюджет производственных расходо'!B33 -> 0 | C37: ='Бюджет производственных расходо'!C33 -> 0 | D37: ='Бюджет производственных расходо'!D33 -> 0 | E37: ='Бюджет производственных расходо'!E33 -> 0 | F37: ='Бюджет производственных расходо'!F33 -> 0 | G37: ='Бюджет производственных расходо'!G33 -> 0 | H37: ='Бюджет производственных расходо'!H33 -> 0 | I37: ='Бюджет производственных расходо'!I33 -> 0 | ... M37: ='Бюджет производственных расходо'!M33 -> 0 | N37: =B37+C37+D37+E37+F37+G37+H37+I37+J37+K37+L37+M37 -> 0
A38: Валовая прибыль | B38: =B4-B6 -> 0 | C38: =C4-C6 -> 0 | D38: =D4-D6 -> 0 | E38: =E4-E6 -> 0 | F38: =F4-F6 -> 0 | G38: =G4-G6 -> 0 | H38: =H4-H6 -> 0 | I38: =I4-I6 -> 0 | ... M38: =M4-M6 -> 0 | N38: =B38+C38+D38+E38+F38+G38+H38+I38+J38+K38+L38+M38 -> 0
A39: в % от дохода | B39: =IFERROR(B38/B4,) | C39: =IFERROR(C38/C4,) | D39: =IFERROR(D38/D4,) | E39: =IFERROR(E38/E4,) | F39: =IFERROR(F38/F4,) | G39: =IFERROR(G38/G4,) | H39: =IFERROR(H38/H4,) | I39: =IFERROR(I38/I4,) | ... N39: =IFERROR(N38/N4,)
A40: Коммерческие расходы | B40: =B41+B45+B46 -> 0 | C40: =C41+C45+C46 -> 0 | D40: =D41+D45+D46 -> 0 | E40: =E41+E45+E46 -> 0 | F40: =F41+F45+F46 -> 0 | G40: =G41+G45+G46 -> 0 | H40: =H41+H45+H46 -> 0 | I40: =I41+I45+I46 -> 0 | ... M40: =M41+M45+M46 -> 0 | N40: =B40+C40+D40+E40+F40+G40+H40+I40+J40+K40+L40+M40 -> 0
...

Sheet Бюджет-продаж
A1: Бюджет продаж 2021
A2: Наименование статьи | B2: янв | C2: фев | D2: мар | E2: апр | F2: май | G2: июн | H2: июл | I2: авг | J2: сен | K2: окт | L2: ноя | M2: дек | N2: ГОД
A3: ШАГ № 1:ВВОД ИСХОДНОЙ ИНФОРМАЦИИ
A4: Ввести запланированные продажи ГП по направлениям, единицы
A5: Направление 1
A6: Продукт 1 | N6: =SUM(B6,C6,D6,E6,F6,G6,H6,I6,J6,K6,L6,M6) -> 0
A7: Продукт 2 | N7: =SUM(B7,C7,D7,E7,F7,G7,H7,I7,J7,K7,L7,M7) -> 0
A8: Продукт 3 | N8: =SUM(B8,C8,D8,E8,F8,G8,H8,I8,J8,K8,L8,M8) -> 0
A9: Продукт 4 | N9: =SUM(B9,C9,D9,E9,F9,G9,H9,I9,J9,K9,L9,M9) -> 0
A10: Продукт 5 | N10: =SUM(B10,C10,D10,E10,F10,G10,H10,I10,J10,K10,L10,M10) -> 0
A11: Продукт.... | N11: =SUM(B11,C11,D11,E11,F11,G11,H11,I11,J11,K11,L11,M11) -> 0
N12: =SUM(B12,C12,D12,E12,F12,G12,H12,I12,J12,K12,L12,M12) -> 0
N13: =SUM(B13,C13,D13,E13,F13,G13,H13,I13,J13,K13,L13,M13) -> 0
N14: =SUM(B14,C14,D14,E14,F14,G14,H14,I14,J14,K14,L14,M14) -> 0
N15: =SUM(B15,C15,D15,E15,F15,G15,H15,I15,J15,K15,L15,M15) -> 0
N16: =SUM(B16,C16,D16,E16,F16,G16,H16,I16,J16,K16,L16,M16) -> 0
N17: =SUM(B17,C17,D17,E17,F17,G17,H17,I17,J17,K17,L17,M17) -> 0
N18: =SUM(B18,C18,D18,E18,F18,G18,H18,I18,J18,K18,L18,M18) -> 0
N19: =SUM(B19,C19,D19,E19,F19,G19,H19,I19,J19,K19,L19,M19) -> 0
N20: =SUM(B20,C20,D20,E20,F20,G20,H20,I20,J20,K20,L20,M20) -> 0
N21: =SUM(B21,C21,D21,E21,F21,G21,H21,I21,J21,K21,L21,M21) -> 0
N22: =SUM(B22,C22,D22,E22,F22,G22,H22,I22,J22,K22,L22,M22) -> 0
N23: =SUM(B23,C23,D23,E23,F23,G23,H23,I23,J23,K23,L23,M23) -> 0
... N25: =SUM(B25,C25,D25,E25,F25,G25,H25,I25,J25,K25,L25,M25) -> 0
A26: Итого по направлению 1, единицы | B26: =SUM(B6:B24) -> 0 | C26: =SUM(C6:C24) -> 0 | D26: =SUM(D6:D24) -> 0 | E26: =SUM(E6:E24) -> 0 | F26: =SUM(F6:F24) -> 0 | G26: =SUM(G6:G24) -> 0 | H26: =SUM(H6:H24) -> 0 | I26: =SUM(I6:I24) -> 0 | ... N26: =SUM(N6:N24) -> 0
A28: Направление 2
A29: Продукт 1
A30: Продукт 2 | N30: =SUM(B30,C30,D30,E30,F30,G30,H30,I30,J30,K30,L30,M30) -> 0
A31: Продукт 3 | N31: =SUM(B31,C31,D31,E31,F31,G31,H31,I31,J31,K31,L31,M31) -> 0
A32: Продукт 4 | N32: =SUM(B32,C32,D32,E32,F32,G32,H32,I32,J32,K32,L32,M32) -> 0
A33: Продукт 5 | N33: =SUM(B33,C33,D33,E33,F33,G33,H33,I33,J33,K33,L33,M33) -> 0
A34: Продукт.... | N34: =SUM(B34,C34,D34,E34,F34,G34,H34,I34,J34,K34,L34,M34) -> 0
N35: =SUM(B35,C35,D35,E35,F35,G35,H35,I35,J35,K35,L35,M35) -> 0
N36: =SUM(B36,C36,D36,E36,F36,G36,H36,I36,J36,K36,L36,M36) -> 0
N37: =SUM(B37,C37,D37,E37,F37,G37,H37,I37,J37,K37,L37,M37) -> 0
N38: =SUM(B38,C38,D38,E38,F38,G38,H38,I38,J38,K38,L38,M38) -> 0
N39: =SUM(B39,C39,D39,E39,F39,G39,H39,I39,J39,K39,L39,M39) -> 0
N40: =SUM(B40,C40,D40,E40,F40,G40,H40,I40,J40,K40,L40,M40) -> 0
N41: =SUM(B41,C41,D41,E41,F41,G41,H41,I41,J41,K41,L41,M41) -> 0
N42: =SUM(B42,C42,D42,E42,F42,G42,H42,I42,J42,K42,L42,M42) -> 0
...

Sheet Бюджет производства
A1: Бюджет производства 2021
A2: Наименование статьи | B2: янв | C2: фев | D2: мар | E2: апр | F2: май | G2: июн | H2: июл | I2: авг | J2: сен | K2: окт | L2: ноя | M2: дек | N2: ГОД
A3: Объем производства продукции
A4: Продукт 1 | B4: ='Бюджет-продаж'!B6+'Бюджет-продаж'!B29 -> 0 | C4: ='Бюджет-продаж'!C6+'Бюджет-продаж'!C29 -> 0 | D4: ='Бюджет-продаж'!D6+'Бюджет-продаж'!D29 -> 0 | E4: ='Бюджет-продаж'!E6+'Бюджет-продаж'!E29 -> 0 | F4: ='Бюджет-продаж'!F6+'Бюджет-продаж'!F29 -> 0 | G4: ='Бюджет-продаж'!G6+'Бюджет-продаж'!G29 -> 0 | H4: ='Бюджет-продаж'!H6+'Бюджет-продаж'!H29 -> 0 | I4: ='Бюджет-продаж'!I6+'Бюджет-продаж'!I29 -> 0 | ... M4: ='Бюджет-продаж'!M6+'Бюджет-продаж'!M29 -> 0 | N4: =SUM(B4,C4,D4,E4,F4,G4,H4,I4,J4,K4,L4,M4) -> 0
A5: Продукт 2 | B5: ='Бюджет-продаж'!B7+'Бюджет-продаж'!B30 -> 0 | C5: ='Бюджет-продаж'!C7+'Бюджет-продаж'!C30 -> 0 | D5: ='Бюджет-продаж'!D7+'Бюджет-продаж'!D30 -> 0 | E5: ='Бюджет-продаж'!E7+'Бюджет-продаж'!E30 -> 0 | F5: ='Бюджет-продаж'!F7+'Бюджет-продаж'!F30 -> 0 | G5: ='Бюджет-продаж'!G7+'Бюджет-продаж'!G30 -> 0 | H5: ='Бюджет-продаж'!H7+'Бюджет-продаж'!H30 -> 0 | I5: ='Бюджет-продаж'!I7+'Бюджет-продаж'!I30 -> 0 | ... M5: ='Бюджет-продаж'!M7+'Бюджет-продаж'!M30 -> 0 | N5: =SUM(B5,C5,D5,E5,F5,G5,H5,I5,J5,K5,L5,M5) -> 0
A6: Продукт 3 | B6: ='Бюджет-продаж'!B8+'Бюджет-продаж'!B31 -> 0 | C6: ='Бюджет-продаж'!C8+'Бюджет-продаж'!C31 -> 0 | D6: ='Бюджет-продаж'!D8+'Бюджет-продаж'!D31 -> 0 | E6: ='Бюджет-продаж'!E8+'Бюджет-продаж'!E31 -> 0 | F6: ='Бюджет-продаж'!F8+'Бюджет-продаж'!F31 -> 0 | G6: ='Бюджет-продаж'!G8+'Бюджет-продаж'!G31 -> 0 | H6: ='Бюджет-продаж'!H8+'Бюджет-продаж'!H31 -> 0 | I6: ='Бюджет-продаж'!I8+'Бюджет-продаж'!I31 -> 0 | ... M6: ='Бюджет-продаж'!M8+'Бюджет-продаж'!M31 -> 0 | N6: =SUM(B6,C6,D6,E6,F6,G6,H6,I6,J6,K6,L6,M6) -> 0
A7: Продукт 4 | B7: ='Бюджет-продаж'!B9+'Бюджет-продаж'!B32 -> 0 | C7: ='Бюджет-продаж'!C9+'Бюджет-продаж'!C32 -> 0 | D7: ='Бюджет-продаж'!D9+'Бюджет-продаж'!D32 -> 0 | E7: ='Бюджет-продаж'!E9+'Бюджет-продаж'!E32 -> 0 | F7: ='Бюджет-продаж'!F9+'Бюджет-продаж'!F32 -> 0 | G7: ='Бюджет-продаж'!G9+'Бюджет-продаж'!G32 -> 0 | H7: ='Бюджет-продаж'!H9+'Бюджет-продаж'!H32 -> 0 | I7: ='Бюджет-продаж'!I9+'Бюджет-продаж'!I32 -> 0 | ... M7: ='Бюджет-продаж'!M9+'Бюджет-продаж'!M32 -> 0 | N7: =SUM(B7,C7,D7,E7,F7,G7,H7,I7,J7,K7,L7,M7) -> 0
A8: Продукт 5 | B8: ='Бюджет-продаж'!B10+'Бюджет-продаж'!B33 -> 0 | C8: ='Бюджет-продаж'!C10+'Бюджет-продаж'!C33 -> 0 | D8: ='Бюджет-продаж'!D10+'Бюджет-продаж'!D33 -> 0 | E8: ='Бюджет-продаж'!E10+'Бюджет-продаж'!E33 -> 0 | F8: ='Бюджет-продаж'!F10+'Бюджет-продаж'!F33 -> 0 | G8: ='Бюджет-продаж'!G10+'Бюджет-продаж'!G33 -> 0 | H8: ='Бюджет-продаж'!H10+'Бюджет-продаж'!H33 -> 0 | I8: ='Бюджет-продаж'!I10+'Бюджет-продаж'!I33 -> 0 | ... M8: ='Бюджет-продаж'!M10+'Бюджет-продаж'!M33 -> 0 | N8: =SUM(B8,C8,D8,E8,F8,G8,H8,I8,J8,K8,L8,M8) -> 0
A9: Продукт.... | B9: ='Бюджет-продаж'!B11+'Бюджет-продаж'!B34 -> 0 | C9: ='Бюджет-продаж'!C11+'Бюджет-продаж'!C34 -> 0 | D9: ='Бюджет-продаж'!D11+'Бюджет-продаж'!D34 -> 0 | E9: ='Бюджет-продаж'!E11+'Бюджет-продаж'!E34 -> 0 | F9: ='Бюджет-продаж'!F11+'Бюджет-продаж'!F34 -> 0 | G9: ='Бюджет-продаж'!G11+'Бюджет-продаж'!G34 -> 0 | H9: ='Бюджет-продаж'!H11+'Бюджет-продаж'!H34 -> 0 | I9: ='Бюджет-продаж'!I11+'Бюджет-продаж'!I34 -> 0 | ... M9: ='Бюджет-продаж'!M11+'Бюджет-продаж'!M34 -> 0 | N9: =SUM(B9,C9,D9,E9,F9,G9,H9,I9,J9,K9,L9,M9) -> 0
B10: ='Бюджет-продаж'!B12+'Бюджет-продаж'!B35 -> 0 | C10: ='Бюджет-продаж'!C12+'Бюджет-продаж'!C35 -> 0 | D10: ='Бюджет-продаж'!D12+'Бюджет-продаж'!D35 -> 0 | E10: ='Бюджет-продаж'!E12+'Бюджет-продаж'!E35 -> 0 | F10: ='Бюджет-продаж'!F12+'Бюджет-продаж'!F35 -> 0 | G10: ='Бюджет-продаж'!G12+'Бюджет-продаж'!G35 -> 0 | H10: ='Бюджет-продаж'!H12+'Бюджет-продаж'!H35 -> 0 | I10: ='Бюджет-продаж'!I12+'Бюджет-продаж'!I35 -> 0 | ... M10: ='Бюджет-продаж'!M12+'Бюджет-продаж'!M35 -> 0 | N10: =SUM(B10,C10,D10,E10,F10,G10,H10,I10,J10,K10,L10,M10) -> 0
B11: ='Бюджет-продаж'!B13+'Бюджет-продаж'!B36 -> 0 | C11: ='Бюджет-продаж'!C13+'Бюджет-продаж'!C36 -> 0 | D11: ='Бюджет-продаж'!D13+'Бюджет-продаж'!D36 -> 0 | E11: ='Бюджет-продаж'!E13+'Бюджет-продаж'!E36 -> 0 | F11: ='Бюджет-продаж'!F13+'Бюджет-продаж'!F36 -> 0 | G11: ='Бюджет-продаж'!G13+'Бюджет-продаж'!G36 -> 0 | H11: ='Бюджет-продаж'!H13+'Бюджет-продаж'!H36 -> 0 | I11: ='Бюджет-продаж'!I13+'Бюджет-продаж'!I36 -> 0 | ... M11: ='Бюджет-продаж'!M13+'Бюджет-продаж'!M36 -> 0 | N11: =SUM(B11,C11,D11,E11,F11,G11,H11,I11,J11,K11,L11,M11) -> 0
B12: ='Бюджет-продаж'!B14+'Бюджет-продаж'!B37 -> 0 | C12: ='Бюджет-продаж'!C14+'Бюджет-продаж'!C37 -> 0 | D12: ='Бюджет-продаж'!D14+'Бюджет-продаж'!D37 -> 0 | E12: ='Бюджет-продаж'!E14+'Бюджет-продаж'!E37 -> 0 | F12: ='Бюджет-продаж'!F14+'Бюджет-продаж'!F37 -> 0 | G12: ='Бюджет-продаж'!G14+'Бюджет-продаж'!G37 -> 0 | H12: ='Бюджет-продаж'!H14+'Бюджет-продаж'!H37 -> 0 | I12: ='Бюджет-продаж'!I14+'Бюджет-продаж'!I37 -> 0 | ... M12: ='Бюджет-продаж'!M14+'Бюджет-продаж'!M37 -> 0 | N12: =SUM(B12,C12,D12,E12,F12,G12,H12,I12,J12,K12,L12,M12) -> 0
B13: ='Бюджет-продаж'!B15+'Бюджет-продаж'!B38 -> 0 | C13: ='Бюджет-продаж'!C15+'Бюджет-продаж'!C38 -> 0 | D13: ='Бюджет-продаж'!D15+'Бюджет-продаж'!D38 -> 0 | E13: ='Бюджет-продаж'!E15+'Бюджет-продаж'!E38 -> 0 | F13: ='Бюджет-продаж'!F15+'Бюджет-продаж'!F38 -> 0 | G13: ='Бюджет-продаж'!G15+'Бюджет-продаж'!G38 -> 0 | H13: ='Бюджет-продаж'!H15+'Бюджет-продаж'!H38 -> 0 | I13: ='Бюджет-продаж'!I15+'Бюджет-продаж'!I38 -> 0 | ... M13: ='Бюджет-продаж'!M15+'Бюджет-продаж'!M38 -> 0 | N13: =SUM(B13,C13,D13,E13,F13,G13,H13,I13,J13,K13,L13,M13) -> 0
B14: ='Бюджет-продаж'!B16+'Бюджет-продаж'!B39 -> 0 | C14: ='Бюджет-продаж'!C16+'Бюджет-продаж'!C39 -> 0 | D14: ='Бюджет-продаж'!D16+'Бюджет-продаж'!D39 -> 0 | E14: ='Бюджет-продаж'!E16+'Бюджет-продаж'!E39 -> 0 | F14: ='Бюджет-продаж'!F16+'Бюджет-продаж'!F39 -> 0 | G14: ='Бюджет-продаж'!G16+'Бюджет-продаж'!G39 -> 0 | H14: ='Бюджет-продаж'!H16+'Бюджет-продаж'!H39 -> 0 | I14: ='Бюджет-продаж'!I16+'Бюджет-продаж'!I39 -> 0 | ... M14: ='Бюджет-продаж'!M16+'Бюджет-продаж'!M39 -> 0 | N14: =SUM(B14,C14,D14,E14,F14,G14,H14,I14,J14,K14,L14,M14) -> 0
B15: ='Бюджет-продаж'!B17+'Бюджет-продаж'!B40 -> 0 | C15: ='Бюджет-продаж'!C17+'Бюджет-продаж'!C40 -> 0 | D15: ='Бюджет-продаж'!D17+'Бюджет-продаж'!D40 -> 0 | E15: ='Бюджет-продаж'!E17+'Бюджет-продаж'!E40 -> 0 | F15: ='Бюджет-продаж'!F17+'Бюджет-продаж'!F40 -> 0 | G15: ='Бюджет-продаж'!G17+'Бюджет-продаж'!G40 -> 0 | H15: ='Бюджет-продаж'!H17+'Бюджет-продаж'!H40 -> 0 | I15: ='Бюджет-продаж'!I17+'Бюджет-продаж'!I40 -> 0 | ... M15: ='Бюджет-продаж'!M17+'Бюджет-продаж'!M40 -> 0 | N15: =SUM(B15,C15,D15,E15,F15,G15,H15,I15,J15,K15,L15,M15) -> 0
B16: ='Бюджет-продаж'!B18+'Бюджет-продаж'!B41 -> 0 | C16: ='Бюджет-продаж'!C18+'Бюджет-продаж'!C41 -> 0 | D16: ='Бюджет-продаж'!D18+'Бюджет-продаж'!D41 -> 0 | E16: ='Бюджет-продаж'!E18+'Бюджет-продаж'!E41 -> 0 | F16: ='Бюджет-продаж'!F18+'Бюджет-продаж'!F41 -> 0 | G16: ='Бюджет-продаж'!G18+'Бюджет-продаж'!G41 -> 0 | H16: ='Бюджет-продаж'!H18+'Бюджет-продаж'!H41 -> 0 | I16: ='Бюджет-продаж'!I18+'Бюджет-продаж'!I41 -> 0 | ... M16: ='Бюджет-продаж'!M18+'Бюджет-продаж'!M41 -> 0 | N16: =SUM(B16,C16,D16,E16,F16,G16,H16,I16,J16,K16,L16,M16) -> 0
B17: ='Бюджет-продаж'!B19+'Бюджет-продаж'!B42 -> 0 | C17: ='Бюджет-продаж'!C19+'Бюджет-продаж'!C42 -> 0 | D17: ='Бюджет-продаж'!D19+'Бюджет-продаж'!D42 -> 0 | E17: ='Бюджет-продаж'!E19+'Бюджет-продаж'!E42 -> 0 | F17: ='Бюджет-продаж'!F19+'Бюджет-продаж'!F42 -> 0 | G17: ='Бюджет-продаж'!G19+'Бюджет-продаж'!G42 -> 0 | H17: ='Бюджет-продаж'!H19+'Бюджет-продаж'!H42 -> 0 | I17: ='Бюджет-продаж'!I19+'Бюджет-продаж'!I42 -> 0 | ... M17: ='Бюджет-продаж'!M19+'Бюджет-продаж'!M42 -> 0 | N17: =SUM(B17,C17,D17,E17,F17,G17,H17,I17,J17,K17,L17,M17) -> 0
B18: ='Бюджет-продаж'!B20+'Бюджет-продаж'!B43 -> 0 | C18: ='Бюджет-продаж'!C20+'Бюджет-продаж'!C43 -> 0 | D18: ='Бюджет-продаж'!D20+'Бюджет-продаж'!D43 -> 0 | E18: ='Бюджет-продаж'!E20+'Бюджет-продаж'!E43 -> 0 | F18: ='Бюджет-продаж'!F20+'Бюджет-продаж'!F43 -> 0 | G18: ='Бюджет-продаж'!G20+'Бюджет-продаж'!G43 -> 0 | H18: ='Бюджет-продаж'!H20+'Бюджет-продаж'!H43 -> 0 | I18: ='Бюджет-продаж'!I20+'Бюджет-продаж'!I43 -> 0 | ... M18: ='Бюджет-продаж'!M20+'Бюджет-продаж'!M43 -> 0 | N18: =SUM(B18,C18,D18,E18,F18,G18,H18,I18,J18,K18,L18,M18) -> 0
B19: ='Бюджет-продаж'!B21+'Бюджет-продаж'!B44 -> 0 | C19: ='Бюджет-продаж'!C21+'Бюджет-продаж'!C44 -> 0 | D19: ='Бюджет-продаж'!D21+'Бюджет-продаж'!D44 -> 0 | E19: ='Бюджет-продаж'!E21+'Бюджет-продаж'!E44 -> 0 | F19: ='Бюджет-продаж'!F21+'Бюджет-продаж'!F44 -> 0 | G19: ='Бюджет-продаж'!G21+'Бюджет-продаж'!G44 -> 0 | H19: ='Бюджет-продаж'!H21+'Бюджет-продаж'!H44 -> 0 | I19: ='Бюджет-продаж'!I21+'Бюджет-продаж'!I44 -> 0 | ... M19: ='Бюджет-продаж'!M21+'Бюджет-продаж'!M44 -> 0 | N19: =SUM(B19,C19,D19,E19,F19,G19,H19,I19,J19,K19,L19,M19) -> 0
B20: ='Бюджет-продаж'!B22+'Бюджет-продаж'!B45 -> 0 | C20: ='Бюджет-продаж'!C22+'Бюджет-продаж'!C45 -> 0 | D20: ='Бюджет-продаж'!D22+'Бюджет-продаж'!D45 -> 0 | E20: ='Бюджет-продаж'!E22+'Бюджет-продаж'!E45 -> 0 | F20: ='Бюджет-продаж'!F22+'Бюджет-продаж'!F45 -> 0 | G20: ='Бюджет-продаж'!G22+'Бюджет-продаж'!G45 -> 0 | H20: ='Бюджет-продаж'!H22+'Бюджет-продаж'!H45 -> 0 | I20: ='Бюджет-продаж'!I22+'Бюджет-продаж'!I45 -> 0 | ... M20: ='Бюджет-продаж'!M22+'Бюджет-продаж'!M45 -> 0 | N20: =SUM(B20,C20,D20,E20,F20,G20,H20,I20,J20,K20,L20,M20) -> 0
B21: ='Бюджет-продаж'!B23+'Бюджет-продаж'!B46 -> 0 | C21: ='Бюджет-продаж'!C23+'Бюджет-продаж'!C46 -> 0 | D21: ='Бюджет-продаж'!D23+'Бюджет-продаж'!D46 -> 0 | E21: ='Бюджет-продаж'!E23+'Бюджет-продаж'!E46 -> 0 | F21: ='Бюджет-продаж'!F23+'Бюджет-продаж'!F46 -> 0 | G21: ='Бюджет-продаж'!G23+'Бюджет-продаж'!G46 -> 0 | H21: ='Бюджет-продаж'!H23+'Бюджет-продаж'!H46 -> 0 | I21: ='Бюджет-продаж'!I23+'Бюджет-продаж'!I46 -> 0 | ... M21: ='Бюджет-продаж'!M23+'Бюджет-продаж'!M46 -> 0 | N21: =SUM(B21,C21,D21,E21,F21,G21,H21,I21,J21,K21,L21,M21) -> 0
... B23: ='Бюджет-продаж'!B25+'Бюджет-продаж'!B48 -> 0 | C23: ='Бюджет-продаж'!C25+'Бюджет-продаж'!C48 -> 0 | D23: ='Бюджет-продаж'!D25+'Бюджет-продаж'!D48 -> 0 | E23: ='Бюджет-продаж'!E25+'Бюджет-продаж'!E48 -> 0 | F23: ='Бюджет-продаж'!F25+'Бюджет-продаж'!F48 -> 0 | G23: ='Бюджет-продаж'!G25+'Бюджет-продаж'!G48 -> 0 | H23: ='Бюджет-продаж'!H25+'Бюджет-продаж'!H48 -> 0 | I23: ='Бюджет-продаж'!I25+'Бюджет-продаж'!I48 -> 0 | ... M23: ='Бюджет-продаж'!M25+'Бюджет-продаж'!M48 -> 0 | N23: =SUM(B23,C23,D23,E23,F23,G23,H23,I23,J23,K23,L23,M23) -> 0
A24: Итого продукции, единицы | B24: =SUM(B4:B22) -> 0 | C24: =SUM(C4:C22) -> 0 | D24: =SUM(D4:D22) -> 0 | E24: =SUM(E4:E22) -> 0 | F24: =SUM(F4:F22) -> 0 | G24: =SUM(G4:G22) -> 0 | H24: =SUM(H4:H22) -> 0 | I24: =SUM(I4:I22) -> 0 | ... N24: =SUM(N4:N22) -> 0
A27: Производственная мощность
A28: Продукт 1 | N28: =SUM(B28,C28,D28,E28,F28,G28,H28,I28,J28,K28,L28,M28) -> 0
A29: Продукт 2 | N29: =SUM(B29,C29,D29,E29,F29,G29,H29,I29,J29,K29,L29,M29) -> 0
A30: Продукт 3 | N30: =SUM(B30,C30,D30,E30,F30,G30,H30,I30,J30,K30,L30,M30) -> 0
A31: Продукт 4 | N31: =SUM(B31,C31,D31,E31,F31,G31,H31,I31,J31,K31,L31,M31) -> 0
A32: Продукт 5 | N32: =SUM(B32,C32,D32,E32,F32,G32,H32,I32,J32,K32,L32,M32) -> 0
A33: Продукт.... | N33: =SUM(B33,C33,D33,E33,F33,G33,H33,I33,J33,K33,L33,M33) -> 0
N34: =SUM(B34,C34,D34,E34,F34,G34,H34,I34,J34,K34,L34,M34) -> 0
N35: =SUM(B35,C35,D35,E35,F35,G35,H35,I35,J35,K35,L35,M35) -> 0
N36: =SUM(B36,C36,D36,E36,F36,G36,H36,I36,J36,K36,L36,M36) -> 0
N37: =SUM(B37,C37,D37,E37,F37,G37,H37,I37,J37,K37,L37,M37) -> 0
N38: =SUM(B38,C38,D38,E38,F38,G38,H38,I38,J38,K38,L38,M38) -> 0
N39: =SUM(B39,C39,D39,E39,F39,G39,H39,I39,J39,K39,L39,M39) -> 0
N40: =SUM(B40,C40,D40,E40,F40,G40,H40,I40,J40,K40,L40,M40) -> 0
N41: =SUM(B41,C41,D41,E41,F41,G41,H41,I41,J41,K41,L41,M41) -> 0
N42: =SUM(B42,C42,D42,E42,F42,G42,H42,I42,J42,K42,L42,M42) -> 0
N43: =SUM(B43,C43,D43,E43,F43,G43,H43,I43,J43,K43,L43,M43) -> 0
...

Sheet Бюджет запасов ГП
A1: Бюджет запасов готовой продукции 2021
A2: Наименование статьи | B2: Объем запасов ГП на 01.01.2021 | C2: янв | D2: фев | E2: мар | F2: апр | G2: май | H2: июн | I2: июл | J2: авг | K2: сен | L2: окт | M2: ноя | N2: дек | O2: ГОД
A3: Объем запасов ГП, единиц
A4: Продукт 1 | C4: =B4+'Бюджет производства'!B4-'Бюджет-продаж'!B6-'Бюджет-продаж'!B29 -> 0 | D4: =C4+'Бюджет производства'!C4-'Бюджет-продаж'!C6-'Бюджет-продаж'!C29 -> 0 | E4: =D4+'Бюджет производства'!D4-'Бюджет-продаж'!D6-'Бюджет-продаж'!D29 -> 0 | F4: =E4+'Бюджет производства'!E4-'Бюджет-продаж'!E6-'Бюджет-продаж'!E29 -> 0 | G4: =F4+'Бюджет производства'!F4-'Бюджет-продаж'!F6-'Бюджет-продаж'!F29 -> 0 | H4: =G4+'Бюджет производства'!G4-'Бюджет-продаж'!G6-'Бюджет-продаж'!G29 -> 0 | I4: =H4+'Бюджет производства'!H4-'Бюджет-продаж'!H6-'Бюджет-продаж'!H29 -> 0 | J4: =I4+'Бюджет производства'!I4-'Бюджет-продаж'!I6-'Бюджет-продаж'!I29 -> 0 | ... N4: =M4+'Бюджет производства'!M4-'Бюджет-продаж'!M6-'Бюджет-продаж'!M29 -> 0
A5: Продукт 2 | C5: =B5+'Бюджет производства'!B5-'Бюджет-продаж'!B7-'Бюджет-продаж'!B30 -> 0 | D5: =C5+'Бюджет производства'!C5-'Бюджет-продаж'!C7-'Бюджет-продаж'!C30 -> 0 | E5: =D5+'Бюджет производства'!D5-'Бюджет-продаж'!D7-'Бюджет-продаж'!D30 -> 0 | F5: =E5+'Бюджет производства'!E5-'Бюджет-продаж'!E7-'Бюджет-продаж'!E30 -> 0 | G5: =F5+'Бюджет производства'!F5-'Бюджет-продаж'!F7-'Бюджет-продаж'!F30 -> 0 | H5: =G5+'Бюджет производства'!G5-'Бюджет-продаж'!G7-'Бюджет-продаж'!G30 -> 0 | I5: =H5+'Бюджет производства'!H5-'Бюджет-продаж'!H7-'Бюджет-продаж'!H30 -> 0 | J5: =I5+'Бюджет производства'!I5-'Бюджет-продаж'!I7-'Бюджет-продаж'!I30 -> 0 | ... N5: =M5+'Бюджет производства'!M5-'Бюджет-продаж'!M7-'Бюджет-продаж'!M30 -> 0
A6: Продукт 3 | C6: =B6+'Бюджет производства'!B6-'Бюджет-продаж'!B8-'Бюджет-продаж'!B31 -> 0 | D6: =C6+'Бюджет производства'!C6-'Бюджет-продаж'!C8-'Бюджет-продаж'!C31 -> 0 | E6: =D6+'Бюджет производства'!D6-'Бюджет-продаж'!D8-'Бюджет-продаж'!D31 -> 0 | F6: =E6+'Бюджет производства'!E6-'Бюджет-продаж'!E8-'Бюджет-продаж'!E31 -> 0 | G6: =F6+'Бюджет производства'!F6-'Бюджет-продаж'!F8-'Бюджет-продаж'!F31 -> 0 | H6: =G6+'Бюджет производства'!G6-'Бюджет-продаж'!G8-'Бюджет-продаж'!G31 -> 0 | I6: =H6+'Бюджет производства'!H6-'Бюджет-продаж'!H8-'Бюджет-продаж'!H31 -> 0 | J6: =I6+'Бюджет производства'!I6-'Бюджет-продаж'!I8-'Бюджет-продаж'!I31 -> 0 | ... N6: =M6+'Бюджет производства'!M6-'Бюджет-продаж'!M8-'Бюджет-продаж'!M31 -> 0
A7: Продукт 4 | C7: =B7+'Бюджет производства'!B7-'Бюджет-продаж'!B9-'Бюджет-продаж'!B32 -> 0 | D7: =C7+'Бюджет производства'!C7-'Бюджет-продаж'!C9-'Бюджет-продаж'!C32 -> 0 | E7: =D7+'Бюджет производства'!D7-'Бюджет-продаж'!D9-'Бюджет-продаж'!D32 -> 0 | F7: =E7+'Бюджет производства'!E7-'Бюджет-продаж'!E9-'Бюджет-продаж'!E32 -> 0 | G7: =F7+'Бюджет производства'!F7-'Бюджет-продаж'!F9-'Бюджет-продаж'!F32 -> 0 | H7: =G7+'Бюджет производства'!G7-'Бюджет-продаж'!G9-'Бюджет-продаж'!G32 -> 0 | I7: =H7+'Бюджет производства'!H7-'Бюджет-продаж'!H9-'Бюджет-продаж'!H32 -> 0 | J7: =I7+'Бюджет производства'!I7-'Бюджет-продаж'!I9-'Бюджет-продаж'!I32 -> 0 | ... N7: =M7+'Бюджет производства'!M7-'Бюджет-продаж'!M9-'Бюджет-продаж'!M32 -> 0
A8: Продукт 5 | C8: =B8+'Бюджет производства'!B8-'Бюджет-продаж'!B10-'Бюджет-продаж'!B33 -> 0 | D8: =C8+'Бюджет производства'!C8-'Бюджет-продаж'!C10-'Бюджет-продаж'!C33 -> 0 | E8: =D8+'Бюджет производства'!D8-'Бюджет-продаж'!D10-'Бюджет-продаж'!D33 -> 0 | F8: =E8+'Бюджет производства'!E8-'Бюджет-продаж'!E10-'Бюджет-продаж'!E33 -> 0 | G8: =F8+'Бюджет производства'!F8-'Бюджет-продаж'!F10-'Бюджет-продаж'!F33 -> 0 | H8: =G8+'Бюджет производства'!G8-'Бюджет-продаж'!G10-'Бюджет-продаж'!G33 -> 0 | I8: =H8+'Бюджет производства'!H8-'Бюджет-продаж'!H10-'Бюджет-продаж'!H33 -> 0 | J8: =I8+'Бюджет производства'!I8-'Бюджет-продаж'!I10-'Бюджет-продаж'!I33 -> 0 | ... N8: =M8+'Бюджет производства'!M8-'Бюджет-продаж'!M10-'Бюджет-продаж'!M33 -> 0
A9: Продукт.... | C9: =B9+'Бюджет производства'!B9-'Бюджет-продаж'!B11-'Бюджет-продаж'!B34 -> 0 | D9: =C9+'Бюджет производства'!C9-'Бюджет-продаж'!C11-'Бюджет-продаж'!C34 -> 0 | E9: =D9+'Бюджет производства'!D9-'Бюджет-продаж'!D11-'Бюджет-продаж'!D34 -> 0 | F9: =E9+'Бюджет производства'!E9-'Бюджет-продаж'!E11-'Бюджет-продаж'!E34 -> 0 | G9: =F9+'Бюджет производства'!F9-'Бюджет-продаж'!F11-'Бюджет-продаж'!F34 -> 0 | H9: =G9+'Бюджет производства'!G9-'Бюджет-продаж'!G11-'Бюджет-продаж'!G34 -> 0 | I9: =H9+'Бюджет производства'!H9-'Бюджет-продаж'!H11-'Бюджет-продаж'!H34 -> 0 | J9: =I9+'Бюджет производства'!I9-'Бюджет-продаж'!I11-'Бюджет-продаж'!I34 -> 0 | ... N9: =M9+'Бюджет производства'!M9-'Бюджет-продаж'!M11-'Бюджет-продаж'!M34 -> 0
C10: =B10+'Бюджет производства'!B10-'Бюджет-продаж'!B12-'Бюджет-продаж'!B35 -> 0 | D10: =C10+'Бюджет производства'!C10-'Бюджет-продаж'!C12-'Бюджет-продаж'!C35 -> 0 | E10: =D10+'Бюджет производства'!D10-'Бюджет-продаж'!D12-'Бюджет-продаж'!D35 -> 0 | F10: =E10+'Бюджет производства'!E10-'Бюджет-продаж'!E12-'Бюджет-продаж'!E35 -> 0 | G10: =F10+'Бюджет производства'!F10-'Бюджет-продаж'!F12-'Бюджет-продаж'!F35 -> 0 | H10: =G10+'Бюджет производства'!G10-'Бюджет-продаж'!G12-'Бюджет-продаж'!G35 -> 0 | I10: =H10+'Бюджет производства'!H10-'Бюджет-продаж'!H12-'Бюджет-продаж'!H35 -> 0 | J10: =I10+'Бюджет производства'!I10-'Бюджет-продаж'!I12-'Бюджет-продаж'!I35 -> 0 | ... N10: =M10+'Бюджет производства'!M10-'Бюджет-продаж'!M12-'Бюджет-продаж'!M35 -> 0
C11: =B11+'Бюджет производства'!B11-'Бюджет-продаж'!B13-'Бюджет-продаж'!B36 -> 0 | D11: =C11+'Бюджет производства'!C11-'Бюджет-продаж'!C13-'Бюджет-продаж'!C36 -> 0 | E11: =D11+'Бюджет производства'!D11-'Бюджет-продаж'!D13-'Бюджет-продаж'!D36 -> 0 | F11: =E11+'Бюджет производства'!E11-'Бюджет-продаж'!E13-'Бюджет-продаж'!E36 -> 0 | G11: =F11+'Бюджет производства'!F11-'Бюджет-продаж'!F13-'Бюджет-продаж'!F36 -> 0 | H11: =G11+'Бюджет производства'!G11-'Бюджет-продаж'!G13-'Бюджет-продаж'!G36 -> 0 | I11: =H11+'Бюджет производства'!H11-'Бюджет-продаж'!H13-'Бюджет-продаж'!H36 -> 0 | J11: =I11+'Бюджет производства'!I11-'Бюджет-продаж'!I13-'Бюджет-продаж'!I36 -> 0 | ... N11: =M11+'Бюджет производства'!M11-'Бюджет-продаж'!M13-'Бюджет-продаж'!M36 -> 0
C12: =B12+'Бюджет производства'!B12-'Бюджет-продаж'!B14-'Бюджет-продаж'!B37 -> 0 | D12: =C12+'Бюджет производства'!C12-'Бюджет-продаж'!C14-'Бюджет-продаж'!C37 -> 0 | E12: =D12+'Бюджет производства'!D12-'Бюджет-продаж'!D14-'Бюджет-продаж'!D37 -> 0 | F12: =E12+'Бюджет производства'!E12-'Бюджет-продаж'!E14-'Бюджет-продаж'!E37 -> 0 | G12: =F12+'Бюджет производства'!F12-'Бюджет-продаж'!F14-'Бюджет-продаж'!F37 -> 0 | H12: =G12+'Бюджет производства'!G12-'Бюджет-продаж'!G14-'Бюджет-продаж'!G37 -> 0 | I12: =H12+'Бюджет производства'!H12-'Бюджет-продаж'!H14-'Бюджет-продаж'!H37 -> 0 | J12: =I12+'Бюджет производства'!I12-'Бюджет-продаж'!I14-'Бюджет-продаж'!I37 -> 0 | ... N12: =M12+'Бюджет производства'!M12-'Бюджет-продаж'!M14-'Бюджет-продаж'!M37 -> 0
C13: =B13+'Бюджет производства'!B13-'Бюджет-продаж'!B15-'Бюджет-продаж'!B38 -> 0 | D13: =C13+'Бюджет производства'!C13-'Бюджет-продаж'!C15-'Бюджет-продаж'!C38 -> 0 | E13: =D13+'Бюджет производства'!D13-'Бюджет-продаж'!D15-'Бюджет-продаж'!D38 -> 0 | F13: =E13+'Бюджет производства'!E13-'Бюджет-продаж'!E15-'Бюджет-продаж'!E38 -> 0 | G13: =F13+'Бюджет производства'!F13-'Бюджет-продаж'!F15-'Бюджет-продаж'!F38 -> 0 | H13: =G13+'Бюджет производства'!G13-'Бюджет-продаж'!G15-'Бюджет-продаж'!G38 -> 0 | I13: =H13+'Бюджет производства'!H13-'Бюджет-продаж'!H15-'Бюджет-продаж'!H38 -> 0 | J13: =I13+'Бюджет производства'!I13-'Бюджет-продаж'!I15-'Бюджет-продаж'!I38 -> 0 | ... N13: =M13+'Бюджет производства'!M13-'Бюджет-продаж'!M15-'Бюджет-продаж'!M38 -> 0
C14: =B14+'Бюджет производства'!B14-'Бюджет-продаж'!B16-'Бюджет-продаж'!B39 -> 0 | D14: =C14+'Бюджет производства'!C14-'Бюджет-продаж'!C16-'Бюджет-продаж'!C39 -> 0 | E14: =D14+'Бюджет производства'!D14-'Бюджет-продаж'!D16-'Бюджет-продаж'!D39 -> 0 | F14: =E14+'Бюджет производства'!E14-'Бюджет-продаж'!E16-'Бюджет-продаж'!E39 -> 0 | G14: =F14+'Бюджет производства'!F14-'Бюджет-продаж'!F16-'Бюджет-продаж'!F39 -> 0 | H14: =G14+'Бюджет производства'!G14-'Бюджет-продаж'!G16-'Бюджет-продаж'!G39 -> 0 | I14: =H14+'Бюджет производства'!H14-'Бюджет-продаж'!H16-'Бюджет-продаж'!H39 -> 0 | J14: =I14+'Бюджет производства'!I14-'Бюджет-продаж'!I16-'Бюджет-продаж'!I39 -> 0 | ... N14: =M14+'Бюджет производства'!M14-'Бюджет-продаж'!M16-'Бюджет-продаж'!M39 -> 0
C15: =B15+'Бюджет производства'!B15-'Бюджет-продаж'!B17-'Бюджет-продаж'!B40 -> 0 | D15: =C15+'Бюджет производства'!C15-'Бюджет-продаж'!C17-'Бюджет-продаж'!C40 -> 0 | E15: =D15+'Бюджет производства'!D15-'Бюджет-продаж'!D17-'Бюджет-продаж'!D40 -> 0 | F15: =E15+'Бюджет производства'!E15-'Бюджет-продаж'!E17-'Бюджет-продаж'!E40 -> 0 | G15: =F15+'Бюджет производства'!F15-'Бюджет-продаж'!F17-'Бюджет-продаж'!F40 -> 0 | H15: =G15+'Бюджет производства'!G15-'Бюджет-продаж'!G17-'Бюджет-продаж'!G40 -> 0 | I15: =H15+'Бюджет производства'!H15-'Бюджет-продаж'!H17-'Бюджет-продаж'!H40 -> 0 | J15: =I15+'Бюджет производства'!I15-'Бюджет-продаж'!I17-'Бюджет-продаж'!I40 -> 0 | ... N15: =M15+'Бюджет производства'!M15-'Бюджет-продаж'!M17-'Бюджет-продаж'!M40 -> 0
C16: =B16+'Бюджет производства'!B16-'Бюджет-продаж'!B18-'Бюджет-продаж'!B41 -> 0 | D16: =C16+'Бюджет производства'!C16-'Бюджет-продаж'!C18-'Бюджет-продаж'!C41 -> 0 | E16: =D16+'Бюджет производства'!D16-'Бюджет-продаж'!D18-'Бюджет-продаж'!D41 -> 0 | F16: =E16+'Бюджет производства'!E16-'Бюджет-продаж'!E18-'Бюджет-продаж'!E41 -> 0 | G16: =F16+'Бюджет производства'!F16-'Бюджет-продаж'!F18-'Бюджет-продаж'!F41 -> 0 | H16: =G16+'Бюджет производства'!G16-'Бюджет-продаж'!G18-'Бюджет-продаж'!G41 -> 0 | I16: =H16+'Бюджет производства'!H16-'Бюджет-продаж'!H18-'Бюджет-продаж'!H41 -> 0 | J16: =I16+'Бюджет производства'!I16-'Бюджет-продаж'!I18-'Бюджет-продаж'!I41 -> 0 | ... N16: =M16+'Бюджет производства'!M16-'Бюджет-продаж'!M18-'Бюджет-продаж'!M41 -> 0
C17: =B17+'Бюджет производства'!B17-'Бюджет-продаж'!B19-'Бюджет-продаж'!B42 -> 0 | D17: =C17+'Бюджет производства'!C17-'Бюджет-продаж'!C19-'Бюджет-продаж'!C42 -> 0 | E17: =D17+'Бюджет производства'!D17-'Бюджет-продаж'!D19-'Бюджет-продаж'!D42 -> 0 | F17: =E17+'Бюджет производства'!E17-'Бюджет-продаж'!E19-'Бюджет-продаж'!E42 -> 0 | G17: =F17+'Бюджет производства'!F17-'Бюджет-продаж'!F19-'Бюджет-продаж'!F42 -> 0 | H17: =G17+'Бюджет производства'!G17-'Бюджет-продаж'!G19-'Бюджет-продаж'!G42 -> 0 | I17: =H17+'Бюджет производства'!H17-'Бюджет-продаж'!H19-'Бюджет-продаж'!H42 -> 0 | J17: =I17+'Бюджет производства'!I17-'Бюджет-продаж'!I19-'Бюджет-продаж'!I42 -> 0 | ... N17: =M17+'Бюджет производства'!M17-'Бюджет-продаж'!M19-'Бюджет-продаж'!M42 -> 0
C18: =B18+'Бюджет производства'!B18-'Бюджет-продаж'!B20-'Бюджет-продаж'!B43 -> 0 | D18: =C18+'Бюджет производства'!C18-'Бюджет-продаж'!C20-'Бюджет-продаж'!C43 -> 0 | E18: =D18+'Бюджет производства'!D18-'Бюджет-продаж'!D20-'Бюджет-продаж'!D43 -> 0 | F18: =E18+'Бюджет производства'!E18-'Бюджет-продаж'!E20-'Бюджет-продаж'!E43 -> 0 | G18: =F18+'Бюджет производства'!F18-'Бюджет-продаж'!F20-'Бюджет-продаж'!F43 -> 0 | H18: =G18+'Бюджет производства'!G18-'Бюджет-продаж'!G20-'Бюджет-продаж'!G43 -> 0 | I18: =H18+'Бюджет производства'!H18-'Бюджет-продаж'!H20-'Бюджет-продаж'!H43 -> 0 | J18: =I18+'Бюджет производства'!I18-'Бюджет-продаж'!I20-'Бюджет-продаж'!I43 -> 0 | ... N18: =M18+'Бюджет производства'!M18-'Бюджет-продаж'!M20-'Бюджет-продаж'!M43 -> 0
C19: =B19+'Бюджет производства'!B19-'Бюджет-продаж'!B21-'Бюджет-продаж'!B44 -> 0 | D19: =C19+'Бюджет производства'!C19-'Бюджет-продаж'!C21-'Бюджет-продаж'!C44 -> 0 | E19: =D19+'Бюджет производства'!D19-'Бюджет-продаж'!D21-'Бюджет-продаж'!D44 -> 0 | F19: =E19+'Бюджет производства'!E19-'Бюджет-продаж'!E21-'Бюджет-продаж'!E44 -> 0 | G19: =F19+'Бюджет производства'!F19-'Бюджет-продаж'!F21-'Бюджет-продаж'!F44 -> 0 | H19: =G19+'Бюджет производства'!G19-'Бюджет-продаж'!G21-'Бюджет-продаж'!G44 -> 0 | I19: =H19+'Бюджет производства'!H19-'Бюджет-продаж'!H21-'Бюджет-продаж'!H44 -> 0 | J19: =I19+'Бюджет производства'!I19-'Бюджет-продаж'!I21-'Бюджет-продаж'!I44 -> 0 | ... N19: =M19+'Бюджет производства'!M19-'Бюджет-продаж'!M21-'Бюджет-продаж'!M44 -> 0
C20: =B20+'Бюджет производства'!B20-'Бюджет-продаж'!B22-'Бюджет-продаж'!B45 -> 0 | D20: =C20+'Бюджет производства'!C20-'Бюджет-продаж'!C22-'Бюджет-продаж'!C45 -> 0 | E20: =D20+'Бюджет производства'!D20-'Бюджет-продаж'!D22-'Бюджет-продаж'!D45 -> 0 | F20: =E20+'Бюджет производства'!E20-'Бюджет-продаж'!E22-'Бюджет-продаж'!E45 -> 0 | G20: =F20+'Бюджет производства'!F20-'Бюджет-продаж'!F22-'Бюджет-продаж'!F45 -> 0 | H20: =G20+'Бюджет производства'!G20-'Бюджет-продаж'!G22-'Бюджет-продаж'!G45 -> 0 | I20: =H20+'Бюджет производства'!H20-'Бюджет-продаж'!H22-'Бюджет-продаж'!H45 -> 0 | J20: =I20+'Бюджет производства'!I20-'Бюджет-продаж'!I22-'Бюджет-продаж'!I45 -> 0 | ... N20: =M20+'Бюджет производства'!M20-'Бюджет-продаж'!M22-'Бюджет-продаж'!M45 -> 0
C21: =B21+'Бюджет производства'!B21-'Бюджет-продаж'!B23-'Бюджет-продаж'!B46 -> 0 | D21: =C21+'Бюджет производства'!C21-'Бюджет-продаж'!C23-'Бюджет-продаж'!C46 -> 0 | E21: =D21+'Бюджет производства'!D21-'Бюджет-продаж'!D23-'Бюджет-продаж'!D46 -> 0 | F21: =E21+'Бюджет производства'!E21-'Бюджет-продаж'!E23-'Бюджет-продаж'!E46 -> 0 | G21: =F21+'Бюджет производства'!F21-'Бюджет-продаж'!F23-'Бюджет-продаж'!F46 -> 0 | H21: =G21+'Бюджет производства'!G21-'Бюджет-продаж'!G23-'Бюджет-продаж'!G46 -> 0 | I21: =H21+'Бюджет производства'!H21-'Бюджет-продаж'!H23-'Бюджет-продаж'!H46 -> 0 | J21: =I21+'Бюджет производства'!I21-'Бюджет-продаж'!I23-'Бюджет-продаж'!I46 -> 0 | ... N21: =M21+'Бюджет производства'!M21-'Бюджет-продаж'!M23-'Бюджет-продаж'!M46 -> 0
