Workbook

Sheet Регламент
A2: Название документа: | B2: План доходов и расходов | F2: Дата формирования регламента
A3: Цель документа: | B3: Запланировать цели компании по доходам и расходам на определенный период. Оценить точность планирования и выявить причины отклонений. | F3: Дата изменения
A4: Результат отчета: | B4: Точность планирования чистой прибыли 80%-120% | F4: Дата изменения
A5: Платформа ведения: | B5: Гугл-таблицы
A8: Ответственный за ведение и проверку документа:
A9: ФИО/ Перенести в чек-лист | B9: Должность | C9: Какую часть информации заполняют/ Перенести в чек-лист | D9: Источник информации | E9: До какого срока должен быть заполнен документ за месяц/ Перенести дату в чек-лист | F9: За какой срок заполняется документ | G9: Комментарий
C10: 1. Своевременный сбор отчета 2. Проверка актуальности внесенной информации 3. Проверка правильности формирования документа 4. Резервное копирование документа
A13: Ответственные за заполнение документа:
A14: ФИО/При необходимости перенести в чек-лист | B14: Должность | C14: Какую часть информации заполняют/При необходимости перенести в чек-лист | D14: Источник информации | E14: До какого срока должен быть заполнен документ за месяц /При необходимости перенести в чек-лист | F14: За какой срок заполняется документ | G14: Комментарий
A19: Риски, которые могут сорвать сроки отчетности, и способы их решения
A20: Риск | C20: Выход из этого риска
A21: Ответственный за заполнение/ Ответственный за ведение документа уходит в отпуск | C21: Передача полномочий другому ответственному лицу (ФИО лица) на срок отпуска. / Срок сдачи отчетности переносится.
A22: Ответственный за заполнение/ Ответственный за ведение документа заболел | C22: Передача полномочий другому ответственному лицу (ФИО лица). / Срок сдачи отчетности переносится.
A23: Технический сбой | C23: Раз в месяц после презентации отчета создается резервное копирование отчетности в рабочее пространство клиента.
A24: Увольнение ответственного сотрудника | C24: Сотрудник должен передать документ в рабочем состоянии с актуальными данными, зафиксировать дату передачи.
A25: Нарушен срок заполнения отчета | C25: Информировать ответственных сотрудников о сроках заполнения отчета. Добиваться согласия ответственных лиц по срокам заполнения отчета.
A27: Правила работы с документом
A28: Название листа | B28: Описание
A29: Вкладка: Справочник | B29: Заполняется в самом начале работы с документом.
B30: Столбец А - Внести вид расходов
B31: Столбец С - Внести блоки ОПиУ
B32: Столбец D - Внести информацию по направлениям бизнеса
A34: Вкладка: Статьи | B34: Заполняется в самом начале работы с документом
B35: Заполняется только при необходимости добавить статью по согласованию с ответственным за ведение документа
B36: Столбец А - Внести наименование статьи
B37: Столбец В - Внести тип/категорию статьи
B38: Столбец С - Внести информацию об источниках информации
B39: Столбец D - Внести полное описание статьи
B40: Столбец F и далее - Внести отметку если статья относится к данному направлению
B41: ВАЖНО! При добавление статьи подробно расписывать структуру расходов или доходов, а также указать источник откуда берем информацию
A42: Вкладка:1,2,3,4,5,6,7,8,9,1,12 | B42: Рабочий документ. Данные заносятся ежемесячно
B43: Столбец B - Автоматически заполняются блоки ОПиУ из вкладки Статьи
B44: Столбец А - Автоматически отображаются источники информации статей
B45: Столбцы С-H - Внести информацию по фактическим расходам по направлениям
B46: Столбец I - Автоматически рассчитывается сумма по всем направлениям
B47: Столбцы J-O - Внести информацию по плановым расходам по направлениям
B48: Столбец P - Автоматически рассчитывается сумма по всем направлениям
B49: Столбцы Q-S - Автоматически рассчитывается отклонение от плана
B50: Важно! До 5 числа месяца следующего за отчетным: в столбцах "C", "D" (Факт) заносятся фактические данные за отчетный месяц (например: до 5 февраля заполняем Факт за январь)
B51: Важно! До 30 числа текущего месяца: в столбцах "N", "O" (План) заносятся плановые данные на следующий за отчетным месяц (например до 30 января заполняем план на февраль)
...

Sheet Статьи
A1: Наименование статьи | B1: Тип | C1: Источник информации | D1: Описание статьи | E1: Проверка на распределение по направлениям только прямых расходов | F1: {=TRANSPOSE('Справочник'!D2:D10)} -> ООО "Весело живем" | G1: ООО "Некогда грустить" | H1: 3 | I1: 4 | J1: 5 | K1: 6 | L1: 7 | M1: 8 | N1: 9
A2: Выручка от аренды машиноместа | B2: Выручка | C2: 1С сч 90.01 убрать НДС! | E2: =if(and(OR(B2="Косвенные административные",B2="Косвенные коммерческие",B2="Расходы ниже EBITDA"),COUNTIF(F2:N2,TRUE)>0),"По направлениям распредляются только прямые расходы!","ОК") -> ОК | F2: FALSE | G2: FALSE | H2: FALSE | I2: FALSE | J2: FALSE | K2: FALSE | L2: FALSE | M2: FALSE | N2: FALSE
A3: Выручка за грузоперевозки | B3: Выручка | C3: 1С сч 90.01 убрать НДС! | E3: =if(and(OR(B3="Косвенные административные",B3="Косвенные коммерческие",B3="Расходы ниже EBITDA"),COUNTIF(F3:N3,TRUE)>0),"По направлениям распредляются только прямые расходы!","ОК") -> ОК | F3: FALSE | G3: FALSE | H3: FALSE | I3: FALSE | J3: FALSE | K3: FALSE | L3: FALSE | M3: FALSE | N3: FALSE
E4: =if(and(OR(B4="Косвенные административные",B4="Косвенные коммерческие",B4="Расходы ниже EBITDA"),COUNTIF(F4:N4,TRUE)>0),"По направлениям распредляются только прямые расходы!","ОК") -> ОК | F4: FALSE | G4: FALSE | H4: FALSE | I4: FALSE | J4: FALSE | K4: FALSE | L4: FALSE | M4: FALSE | N4: FALSE
A5: Аренда, коммунальные услуги | B5: Административные | C5: 1С | E5: =if(and(OR(B5="Косвенные административные",B5="Косвенные коммерческие",B5="Расходы ниже EBITDA"),COUNTIF(F5:N5,TRUE)>0),"По направлениям распредляются только прямые расходы!","ОК") -> ОК | F5: FALSE | G5: FALSE | H5: FALSE | I5: FALSE | J5: FALSE | K5: FALSE | L5: FALSE | M5: FALSE | N5: FALSE
A6: Аутсорсинг и прочие услуги | B6: Административные | C6: 1С | E6: =if(and(OR(B6="Косвенные административные",B6="Косвенные коммерческие",B6="Расходы ниже EBITDA"),COUNTIF(F6:N6,TRUE)>0),"По направлениям распредляются только прямые расходы!","ОК") -> ОК | F6: FALSE | G6: FALSE | H6: FALSE | I6: FALSE | J6: FALSE | K6: FALSE | L6: FALSE | M6: FALSE | N6: FALSE
A7: Зарплата производственного персонала | B7: Общепроизводственные | C7: 1С | E7: =if(and(OR(B7="Косвенные административные",B7="Косвенные коммерческие",B7="Расходы ниже EBITDA"),COUNTIF(F7:N7,TRUE)>0),"По направлениям распредляются только прямые расходы!","ОК") -> ОК | F7: FALSE | G7: FALSE | H7: FALSE | I7: FALSE | J7: FALSE | K7: FALSE | L7: FALSE | M7: FALSE | N7: FALSE
A8: Командировочные расходы | B8: Административные | C8: 1С | E8: =if(and(OR(B8="Косвенные административные",B8="Косвенные коммерческие",B8="Расходы ниже EBITDA"),COUNTIF(F8:N8,TRUE)>0),"По направлениям распредляются только прямые расходы!","ОК") -> ОК | F8: FALSE | G8: FALSE | H8: FALSE | I8: FALSE | J8: FALSE | K8: FALSE | L8: FALSE | M8: FALSE | N8: FALSE
A9: Комиссии банка | B9: Административные | C9: ДДС отчетного месяца. Без НДС! | E9: =if(and(OR(B9="Косвенные административные",B9="Косвенные коммерческие",B9="Расходы ниже EBITDA"),COUNTIF(F9:N9,TRUE)>0),"По направлениям распредляются только прямые расходы!","ОК") -> ОК | F9: FALSE | G9: FALSE | H9: FALSE | I9: FALSE | J9: FALSE | K9: FALSE | L9: FALSE | M9: FALSE | N9: FALSE
A10: Комиссия топливных компаний | B10: Переменные | C10: ДДС отчетного месяца. Без НДС! | E10: =if(and(OR(B10="Косвенные административные",B10="Косвенные коммерческие",B10="Расходы ниже EBITDA"),COUNTIF(F10:N10,TRUE)>0),"По направлениям распредляются только прямые расходы!","ОК") -> ОК | F10: FALSE | G10: FALSE | H10: FALSE | I10: FALSE | J10: FALSE | K10: FALSE | L10: FALSE | M10: FALSE | N10: FALSE
A11: Курсовые разницы | B11: Расходы ниже EBITDA | C11: ДДС отчетного месяца. Без НДС! | E11: =if(and(OR(B11="Косвенные административные",B11="Косвенные коммерческие",B11="Расходы ниже EBITDA"),COUNTIF(F11:N11,TRUE)>0),"По направлениям распредляются только прямые расходы!","ОК") -> ОК | F11: FALSE | G11: FALSE | H11: FALSE | I11: FALSE | J11: FALSE | K11: FALSE | L11: FALSE | M11: FALSE | N11: FALSE
A12: Налог на прибыль УСН 6% | B12: Расходы ниже EBITDA | C12: 1С | E12: =if(and(OR(B12="Косвенные административные",B12="Косвенные коммерческие",B12="Расходы ниже EBITDA"),COUNTIF(F12:N12,TRUE)>0),"По направлениям распредляются только прямые расходы!","ОК") -> ОК | F12: FALSE | G12: FALSE | H12: FALSE | I12: FALSE | J12: FALSE | K12: FALSE | L12: FALSE | M12: FALSE | N12: FALSE
A13: Налог на прибыль 20% | B13: Расходы ниже EBITDA | C13: 1С | E13: =if(and(OR(B13="Косвенные административные",B13="Косвенные коммерческие",B13="Расходы ниже EBITDA"),COUNTIF(F13:N13,TRUE)>0),"По направлениям распредляются только прямые расходы!","ОК") -> ОК | F13: FALSE | G13: FALSE | H13: FALSE | I13: FALSE | J13: FALSE | K13: FALSE | L13: FALSE | M13: FALSE | N13: FALSE
A14: Обучение сотрудников | B14: Административные | C14: ДДС отчетного месяца. Без НДС! | E14: =if(and(OR(B14="Косвенные административные",B14="Косвенные коммерческие",B14="Расходы ниже EBITDA"),COUNTIF(F14:N14,TRUE)>0),"По направлениям распредляются только прямые расходы!","ОК") -> ОК | F14: FALSE | G14: FALSE | H14: FALSE | I14: FALSE | J14: FALSE | K14: FALSE | L14: FALSE | M14: FALSE | N14: FALSE
A15: Подбор персонала | B15: Административные | C15: ДДС отчетного месяца. Без НДС! | E15: =if(and(OR(B15="Косвенные административные",B15="Косвенные коммерческие",B15="Расходы ниже EBITDA"),COUNTIF(F15:N15,TRUE)>0),"По направлениям распредляются только прямые расходы!","ОК") -> ОК | F15: FALSE | G15: FALSE | H15: FALSE | I15: FALSE | J15: FALSE | K15: FALSE | L15: FALSE | M15: FALSE | N15: FALSE
A16: Подписка на сайты по поиску клиентов | B16: Коммерческие | C16: ДДС отчетного месяца. Без НДС! | E16: =if(and(OR(B16="Косвенные административные",B16="Косвенные коммерческие",B16="Расходы ниже EBITDA"),COUNTIF(F16:N16,TRUE)>0),"По направлениям распредляются только прямые расходы!","ОК") -> ОК | F16: FALSE | G16: FALSE | H16: FALSE | I16: FALSE | J16: FALSE | K16: FALSE | L16: FALSE | M16: FALSE | N16: FALSE
... A30: Штрафы | B30: Административные | C30: ДДС отчетного месяца. Без НДС! | E30: =if(and(OR(B30="Косвенные административные",B30="Косвенные коммерческие",B30="Расходы ниже EBITDA"),COUNTIF(F30:N30,TRUE)>0),"По направлениям распредляются только прямые расходы!","ОК") -> ОК | F30: FALSE | G30: FALSE | H30: FALSE | I30: FALSE | J30: FALSE | K30: FALSE | L30: FALSE | M30: FALSE | N30: FALSE
A31: Оплаты % кредиты | B31: Расходы ниже EBITDA | C31: отчет Учет ФД | E31: =if(and(OR(B31="Косвенные административные",B31="Косвенные коммерческие",B31="Расходы ниже EBITDA"),COUNTIF(F31:N31,TRUE)>0),"По направлениям распредляются только прямые расходы!","ОК") -> ОК | F31: FALSE | G31: FALSE
E32: =if(and(OR(B32="Косвенные административные",B32="Косвенные коммерческие",B32="Расходы ниже EBITDA"),COUNTIF(F32:N32,TRUE)>0),"По направлениям распредляются только прямые расходы!","ОК") -> ОК
E33: =if(and(OR(B33="Косвенные административные",B33="Косвенные коммерческие",B33="Расходы ниже EBITDA"),COUNTIF(F33:N33,TRUE)>0),"По направлениям распредляются только прямые расходы!","ОК") -> ОК
E34: =if(and(OR(B34="Косвенные административные",B34="Косвенные коммерческие",B34="Расходы ниже EBITDA"),COUNTIF(F34:N34,TRUE)>0),"По направлениям распредляются только прямые расходы!","ОК") -> ОК
E35: =if(and(OR(B35="Косвенные административные",B35="Косвенные коммерческие",B35="Расходы ниже EBITDA"),COUNTIF(F35:N35,TRUE)>0),"По направлениям распредляются только прямые расходы!","ОК") -> ОК
E36: =if(and(OR(B36="Косвенные административные",B36="Косвенные коммерческие",B36="Расходы ниже EBITDA"),COUNTIF(F36:N36,TRUE)>0),"По направлениям распредляются только прямые расходы!","ОК") -> ОК
E37: =if(and(OR(B37="Косвенные административные",B37="Косвенные коммерческие",B37="Расходы ниже EBITDA"),COUNTIF(F37:N37,TRUE)>0),"По направлениям распредляются только прямые расходы!","ОК") -> ОК
E38: =if(and(OR(B38="Косвенные административные",B38="Косвенные коммерческие",B38="Расходы ниже EBITDA"),COUNTIF(F38:N38,TRUE)>0),"По направлениям распредляются только прямые расходы!","ОК") -> ОК
E39: =if(and(OR(B39="Косвенные административные",B39="Косвенные коммерческие",B39="Расходы ниже EBITDA"),COUNTIF(F39:N39,TRUE)>0),"По направлениям распредляются только прямые расходы!","ОК") -> ОК
E40: =if(and(OR(B40="Косвенные административные",B40="Косвенные коммерческие",B40="Расходы ниже EBITDA"),COUNTIF(F40:N40,TRUE)>0),"По направлениям распредляются только прямые расходы!","ОК") -> ОК
E41: =if(and(OR(B41="Косвенные административные",B41="Косвенные коммерческие",B41="Расходы ниже EBITDA"),COUNTIF(F41:N41,TRUE)>0),"По направлениям распредляются только прямые расходы!","ОК") -> ОК
E42: =if(and(OR(B42="Косвенные административные",B42="Косвенные коммерческие",B42="Расходы ниже EBITDA"),COUNTIF(F42:N42,TRUE)>0),"По направлениям распредляются только прямые расходы!","ОК") -> ОК
E43: =if(and(OR(B43="Косвенные административные",B43="Косвенные коммерческие",B43="Расходы ниже EBITDA"),COUNTIF(F43:N43,TRUE)>0),"По направлениям распредляются только прямые расходы!","ОК") -> ОК
... E45: =if(and(OR(B45="Косвенные административные",B45="Косвенные коммерческие",B45="Расходы ниже EBITDA"),COUNTIF(F45:N45,TRUE)>0),"По направлениям распредляются только прямые расходы!","ОК") -> ОК

Sheet 1
C1: ФАКТ | J1: План | Q1: Отклонения
A2: Источники | C2: {=TRANSPOSE('Справочник'!D2:D7)} -> ООО "Весело живем" | D2: ООО "Некогда грустить" | E2: 3 | F2: 4 | G2: 5 | H2: 6 | I2: Итого | J2: {=TRANSPOSE('Справочник'!D2:D7)} -> ООО "Весело живем" | K2: ООО "Некогда грустить" | L2: 3 | M2: 4 | N2: 5 | O2: 6 | P2: Итого | Q2: факт-план, руб | R2: факт/план, % | S2: Результат
B3: Выручка | C3: =SUM(C4:C10) -> 225500 | D3: =SUM(D4:D10) -> 2100 | E3: =SUM(E4:E10) -> 0 | F3: =SUM(F4:F10) -> 0 | G3: =SUM(G4:G10) -> 0 | H3: =SUM(H4:H10) -> 0 | I3: =sum(C3:H3) -> 227600 | J3: =SUM(J4:J10) -> 230400 | K3: =SUM(K4:K10) -> 0 | P3: =SUM(P4:P10) -> 230400 | Q3: =I3-P3 -> -2800 | R3: =IFERROR(I3/P3,0) -> 0.98784722 | S3: =IF(Q3=0,"",IF(R3>1,"выполнение","план не выполнен")) -> план не выполнен
A4: =IFERROR(VLOOKUP(B4,'Статьи'!$A$2:C26,3,0)," ") -> 1С сч 90.01 убрать НДС! | B4: =IFERROR(__xludf.DUMMYFUNCTION("iferror(filter('Статьи'!$A$1:$A182,'Статьи'!$B$1:$B182=$B$3))"),"Выручка от аренды машиноместа") -> Выручка от аренды машиноместа | C4: 500 | I4: =SUM(C4:H4) -> 500 | J4: 400 | P4: =SUM(J4:K4) -> 400 | Q4: =I4-P4 -> 100 | R4: =IFERROR(I4/P4,0) -> 1.25 | S4: =IF(Q4=0,"",IF(R4=0,"обратить внимание",IF(R4>1,"выполнение","план не выполнен"))) -> выполнение
A5: =IFERROR(VLOOKUP(B5,'Статьи'!$A$2:C27,3,0)," ") -> 1С сч 90.01 убрать НДС! | B5: =IFERROR(__xludf.DUMMYFUNCTION("""COMPUTED_VALUE"""),"Выручка за грузоперевозки") -> Выручка за грузоперевозки | C5: 225000 | D5: 2100 | I5: =SUM(C5:H5) -> 227100 | J5: 230000 | P5: =SUM(J5:K5) -> 230000 | Q5: =I5-P5 -> -2900 | R5: =IFERROR(I5/P5,0) -> 0.9873913 | S5: =IF(Q5=0,"",IF(R5=0,"обратить внимание",IF(R5>1,"выполнение","план не выполнен"))) -> план не выполнен
A6: =IFERROR(VLOOKUP(B6,'Статьи'!$A$2:C28,3,0)," ") | I6: =SUM(C6:H6) -> 0 | P6: =SUM(F6:J6) -> 0 | Q6: =I6-P6 -> 0 | R6: =IFERROR(I6/P6,0) -> 0 | S6: =IF(Q6=0,"",IF(R6=0,"обратить внимание",IF(R6>1,"выполнение","план не выполнен")))
A7: =IFERROR(VLOOKUP(B7,'Статьи'!$A$2:C29,3,0)," ") | I7: =SUM(C7:H7) -> 0 | P7: =SUM(F7:J7) -> 0 | Q7: =I7-P7 -> 0 | R7: =IFERROR(I7/P7,0) -> 0 | S7: =IF(Q7=0,"",IF(R7=0,"обратить внимание",IF(R7>1,"выполнение","план не выполнен")))
A8: =IFERROR(VLOOKUP(B8,'Статьи'!$A$2:C30,3,0)," ") | I8: =SUM(C8:H8) -> 0 | P8: =SUM(F8:J8) -> 0 | Q8: =I8-P8 -> 0 | R8: =IFERROR(I8/P8,0) -> 0 | S8: =IF(Q8=0,"",IF(R8=0,"обратить внимание",IF(R8>1,"выполнение","план не выполнен")))
A9: =IFERROR(VLOOKUP(B9,'Статьи'!$A$2:C31,3,0)," ") | Q9: =I9-P9 -> 0 | R9: =IFERROR(I9/P9,0) -> 0 | S9: =IF(Q9=0,"",IF(R9=0,"обратить внимание",IF(R9>1,"выполнение","план не выполнен")))
A10: =IFERROR(VLOOKUP(B10,'Статьи'!$A$2:C32,3,0)," ") | Q10: =I10-P10 -> 0 | R10: =IFERROR(I10/P10,0) -> 0 | S10: =IF(Q10=0,"",IF(R10=0,"обратить внимание",IF(R10>1,"выполнение","план не выполнен")))
B11: Производственные расходы | C11: =C12+C58 -> -60769 | D11: =D12+D58 -> -1216 | E11: =E12+E58 -> 0 | F11: =F12+F58 -> 0 | G11: =G12+G58 -> 0 | H11: =H12+H58 -> 0 | I11: =I12+I58 -> -61985 | J11: =J12+J58 -> -73525 | K11: =K12+K58 -> 0 | P11: =P12+P58 -> -73525 | Q11: =I11-P11 -> 11540 | R11: =IFERROR(I11/P11,0) -> 0.84304658 | S11: =IF(Q11=0,"",IF(R11>1,"план не выполнен","выполнение")) -> выполнение
B12: Переменные | C12: =sum(C13:C54) -> -48250 | D12: =sum(D13:D54) -> -1216 | E12: =sum(E13:E54) -> 0 | F12: =sum(F13:F54) -> 0 | G12: =sum(G13:G54) -> 0 | H12: =sum(H13:H54) -> 0 | I12: =sum(I13:I54) -> -49466 | J12: =sum(J13:J54) -> -61250 | K12: =sum(K13:K54) -> 0 | P12: =sum(P13:P54) -> -61250 | Q12: =I12-P12 -> 11784 | R12: =IFERROR(I12/P12,0) -> 0.80760816 | S12: =IF(Q12=0,"",IF(R12>1,"план не выполнен","выполнение")) -> выполнение
A13: =IFERROR(VLOOKUP(B13,'Статьи'!$A$2:C35,3,0)," ") -> ДДС отчетного месяца. Без НДС! | B13: =IFERROR(__xludf.DUMMYFUNCTION("iferror(filter('Статьи'!$A$1:$A182,'Статьи'!$B$1:$B182=$B$12))"),"Комиссия топливных компаний") -> Комиссия топливных компаний | C13: -250 | D13: -16 | I13: =sum(C13:H13) -> -266 | J13: -250 | P13: =SUM(J13:K13) -> -250 | Q13: =I13-P13 -> -16 | R13: =IFERROR(I13/P13,0) -> 1.064 | S13: =IF(Q13=0,"",IF(R13=0,"обратить внимание",IF(R13>1,"перерасход","экономия"))) -> перерасход
A14: =IFERROR(VLOOKUP(B14,'Статьи'!$A$2:C36,3,0)," ") -> 1С | B14: =IFERROR(__xludf.DUMMYFUNCTION("""COMPUTED_VALUE"""),"Топливо для грузовых авто ") -> Топливо для грузовых авто | C14: -48000 | D14: -1200 | I14: =sum(C14:H14) -> -49200 | J14: -61000 | P14: =SUM(J14:K14) -> -61000 | Q14: =I14-P14 -> 11800 | R14: =IFERROR(I14/P14,0) -> 0.80655738 | S14: =IF(Q14=0,"",IF(R14=0,"обратить внимание",IF(R14>1,"перерасход","экономия"))) -> экономия
A15: =IFERROR(VLOOKUP(B15,'Статьи'!$A$2:C37,3,0)," ") | I15: =sum(C15:H15) -> 0 | P15: =SUM(J15:K15) -> 0 | Q15: =I15-P15 -> 0 | R15: =IFERROR(I15/P15,0) -> 0 | S15: =IF(Q15=0,"",IF(R15=0,"обратить внимание",IF(R15>1,"перерасход","экономия")))
A16: =IFERROR(VLOOKUP(B16,'Статьи'!$A$2:C38,3,0)," ") | I16: =sum(C16:H16) -> 0 | P16: =SUM(J16:K16) -> 0 | Q16: =I16-P16 -> 0 | R16: =IFERROR(I16/P16,0) -> 0 | S16: =IF(Q16=0,"",IF(R16=0,"обратить внимание",IF(R16>1,"перерасход","экономия")))
A17: =IFERROR(VLOOKUP(B17,'Статьи'!$A$2:C39,3,0)," ") | I17: =sum(C17:H17) -> 0 | P17: =sum(F17:J17) -> 0 | Q17: =I17-P17 -> 0 | R17: =IFERROR(I17/P17,0) -> 0 | S17: =IF(Q17=0,"",IF(R17=0,"обратить внимание",IF(R17>1,"перерасход","экономия")))
I18: =sum(C18:H18) -> 0 | P18: =sum(F18:J18) -> 0 | Q18: =I18-P18 -> 0 | R18: =IFERROR(I18/P18,0) -> 0 | S18: =IF(Q18=0,0,IF(R18>1,"перерасход","экономия")) -> 0
I19: =sum(C19:H19) -> 0 | P19: =sum(F19:J19) -> 0 | Q19: =I19-P19 -> 0 | R19: =IFERROR(I19/P19,0) -> 0 | S19: =IF(Q19=0,0,IF(R19>1,"перерасход","экономия")) -> 0
I20: =sum(C20:H20) -> 0 | P20: =sum(F20:J20) -> 0 | Q20: =I20-P20 -> 0 | R20: =IFERROR(I20/P20,0) -> 0 | S20: =IF(Q20=0,0,IF(R20>1,"перерасход","экономия")) -> 0
I21: =sum(C21:H21) -> 0 | P21: =sum(F21:J21) -> 0 | Q21: =I21-P21 -> 0 | R21: =IFERROR(I21/P21,0) -> 0 | S21: =IF(Q21=0,0,IF(R21>1,"перерасход","экономия")) -> 0
I22: =sum(C22:H22) -> 0 | P22: =sum(F22:J22) -> 0 | Q22: =I22-P22 -> 0 | R22: =IFERROR(I22/P22,0) -> 0 | S22: =IF(Q22=0,0,IF(R22>1,"перерасход","экономия")) -> 0
I23: =sum(C23:H23) -> 0 | P23: =sum(F23:J23) -> 0 | Q23: =I23-P23 -> 0 | R23: =IFERROR(I23/P23,0) -> 0 | S23: =IF(Q23=0,0,IF(R23>1,"перерасход","экономия")) -> 0
I24: =sum(C24:H24) -> 0 | P24: =sum(F24:J24) -> 0 | Q24: =I24-P24 -> 0 | R24: =IFERROR(I24/P24,0) -> 0 | S24: =IF(Q24=0,0,IF(R24>1,"перерасход","экономия")) -> 0
I25: =sum(C25:H25) -> 0 | P25: =sum(F25:J25) -> 0 | Q25: =I25-P25 -> 0 | R25: =IFERROR(I25/P25,0) -> 0 | S25: =IF(Q25=0,0,IF(R25>1,"перерасход","экономия")) -> 0
I26: =sum(C26:H26) -> 0 | P26: =sum(F26:J26) -> 0 | Q26: =I26-P26 -> 0 | R26: =IFERROR(I26/P26,0) -> 0 | S26: =IF(Q26=0,0,IF(R26>1,"перерасход","экономия")) -> 0
I27: =sum(C27:H27) -> 0 | P27: =sum(F27:J27) -> 0 | Q27: =I27-P27 -> 0 | R27: =IFERROR(I27/P27,0) -> 0 | S27: =IF(Q27=0,0,IF(R27>1,"перерасход","экономия")) -> 0
I28: =sum(C28:H28) -> 0 | P28: =sum(F28:J28) -> 0 | Q28: =I28-P28 -> 0 | R28: =IFERROR(I28/P28,0) -> 0 | S28: =IF(Q28=0,0,IF(R28>1,"перерасход","экономия")) -> 0
I29: =sum(C29:H29) -> 0 | P29: =sum(F29:J29) -> 0 | Q29: =I29-P29 -> 0 | R29: =IFERROR(I29/P29,0) -> 0 | S29: =IF(Q29=0,0,IF(R29>1,"перерасход","экономия")) -> 0
... I54: =sum(C54:H54) -> 0 | P54: =sum(F54:J54) -> 0 | Q54: =I54-P54 -> 0 | R54: =IFERROR(I54/P54,0) -> 0 | S54: =IF(Q54=0,0,IF(R54>1,"перерасход","экономия")) -> 0
B55: Маржинальный доход | C55: =C3+C12 -> 177250 | D55: =D3+D12 -> 884 | E55: =E3+E12 -> 0 | F55: =F3+F12 -> 0 | G55: =G3+G12 -> 0 | H55: =H3+H12 -> 0 | I55: =I3+I12 -> 178134 | J55: =J3+J12 -> 169150 | K55: =K3+K12 -> 0 | P55: =P3+P12 -> 169150 | Q55: =I55-P55 -> 8984 | R55: =IFERROR(I55/P55,0) -> 1.0531126 | S55: =IF(Q55=0,"",IF(R55>1,"выполнение","план не выполнен")) -> выполнение
B56: Рентабельность по марже | C56: =IFERROR(C55/C$3,"") -> 0.78603104 | D56: =IFERROR(D55/D$3,"") -> 0.42095238 | E56: =IFERROR(E55/E$3,"") | F56: =IFERROR(F55/F$3,"") | G56: =IFERROR(G55/G$3,"") | H56: =IFERROR(H55/H$3,"") | I56: =IFERROR(I55/I$3,"") -> 0.78266257 | J56: =IFERROR(J55/J$3,"") -> 0.73415799 | K56: =IFERROR(K55/K$3,"") | P56: =IFERROR(P55/P$3,"") -> 0.73415799
B58: Общепроизводственные | C58: =sum(C59:C79) -> -12519 | D58: =sum(D59:D79) -> 0 | E58: =sum(E59:E79) -> 0 | F58: =sum(F59:F79) -> 0 | G58: =sum(G59:G79) -> 0 | H58: =sum(H59:H79) -> 0 | I58: =SUM(I59:I84) -> -12519 | J58: =SUM(J59:J84) -> -12275 | K58: =SUM(K59:K84) -> 0 | P58: =SUM(P59:P84) -> -12275 | Q58: =I58-P58 -> -244 | R58: =IFERROR(I58/P58,0) -> 1.0198778 | S58: =IF(Q58=0,"",IF(R58>1,"план не выполнен","выполнение")) -> план не выполнен
A59: =IFERROR(VLOOKUP(B59,'Статьи'!$A$2:C81,3,0)," ") -> 1С | B59: =IFERROR(__xludf.DUMMYFUNCTION("iferror(filter('Статьи'!$A$1:$A182,'Статьи'!$B$1:$B182=$B$58))"),"Зарплата производственного персонала") -> Зарплата производственного персонала | C59: -19 | I59: =SUM(C59:H59) -> -19 | J59: -55 | P59: =SUM(J59:K59) -> -55 | Q59: =I59-P59 -> 36 | R59: =IFERROR(I59/P59,0) -> 0.34545455 | S59: =IF(Q59=0,"",IF(R59=0,"обратить внимание",IF(R59>1,"перерасход","экономия"))) -> экономия
A60: =IFERROR(VLOOKUP(B60,'Статьи'!$A$2:C82,3,0)," ") -> ДДС отчетного месяца. Без НДС! | B60: =IFERROR(__xludf.DUMMYFUNCTION("""COMPUTED_VALUE"""),"Таможенные расходы") -> Таможенные расходы | C60: -12500 | I60: =SUM(C60:H60) -> -12500 | J60: -12220 | P60: =SUM(J60:K60) -> -12220 | Q60: =I60-P60 -> -280 | R60: =IFERROR(I60/P60,0) -> 1.0229133 | S60: =IF(Q60=0,"",IF(R60=0,"обратить внимание",IF(R60>1,"перерасход","экономия"))) -> перерасход
A61: =IFERROR(VLOOKUP(B61,'Статьи'!$A$2:C83,3,0)," ") | I61: =SUM(C61:H61) -> 0 | P61: =SUM(J61:K61) -> 0 | Q61: =I61-P61 -> 0 | R61: =IFERROR(I61/P61,0) -> 0 | S61: =IF(Q61=0,"",IF(R61=0,"обратить внимание",IF(R61>1,"перерасход","экономия")))
A62: =IFERROR(VLOOKUP(B62,'Статьи'!$A$2:C84,3,0)," ") | I62: =SUM(C62:H62) -> 0 | P62: =SUM(J62:K62) -> 0 | Q62: =I62-P62 -> 0 | R62: =IFERROR(I62/P62,0) -> 0 | S62: =IF(Q62=0,"",IF(R62=0,"обратить внимание",IF(R62>1,"перерасход","экономия")))
A63: =IFERROR(VLOOKUP(B63,'Статьи'!$A$2:C85,3,0)," ") | I63: =SUM(C63:H63) -> 0 | P63: =SUM(J63:K63) -> 0 | Q63: =I63-P63 -> 0 | R63: =IFERROR(I63/P63,0) -> 0 | S63: =IF(Q63=0,"",IF(R63=0,"обратить внимание",IF(R63>1,"перерасход","экономия")))
A64: =IFERROR(VLOOKUP(B64,'Статьи'!$A$2:C86,3,0)," ") | I64: =SUM(C64:H64) -> 0 | P64: =SUM(J64:K64) -> 0 | Q64: =I64-P64 -> 0 | R64: =IFERROR(I64/P64,0) -> 0 | S64: =IF(Q64=0,"",IF(R64=0,"обратить внимание",IF(R64>1,"перерасход","экономия")))
A65: =IFERROR(VLOOKUP(B65,'Статьи'!$A$2:C87,3,0)," ") | I65: =SUM(C65:H65) -> 0 | P65: =SUM(J65:K65) -> 0 | Q65: =I65-P65 -> 0 | R65: =IFERROR(I65/P65,0) -> 0 | S65: =IF(Q65=0,"",IF(R65=0,"обратить внимание",IF(R65>1,"перерасход","экономия")))
...

Sheet 2
C1: ФАКТ | J1: План | Q1: Отклонения
A2: Источники | C2: {=TRANSPOSE('Справочник'!D2:D7)} -> ООО "Весело живем" | D2: ООО "Некогда грустить" | E2: 3 | F2: 4 | G2: 5 | H2: 6 | I2: Итого | J2: {=TRANSPOSE('Справочник'!D2:D7)} -> ООО "Весело живем" | K2: ООО "Некогда грустить" | L2: 3 | M2: 4 | N2: 5 | O2: 6 | P2: Итого | Q2: факт-план, руб | R2: факт/план, % | S2: Результат
B3: Выручка | C3: =SUM(C4:C10) -> 0 | D3: =SUM(D4:D10) -> 0 | E3: =SUM(E4:E10) -> 0 | F3: =SUM(F4:F10) -> 0 | G3: =SUM(G4:G10) -> 0 | H3: =SUM(H4:H10) -> 0 | I3: =sum(C3:H3) -> 0 | J3: =SUM(J4:J10) -> 0 | K3: =SUM(K4:K10) -> 0 | P3: =SUM(P4:P10) -> 0 | Q3: =I3-P3 -> 0 | R3: =IFERROR(I3/P3,0) -> 0 | S3: =IF(Q3=0,"",IF(R3>1,"выполнение","план не выполнен"))
A4: =IFERROR(VLOOKUP(B4,'Статьи'!$A$2:C26,3,0)," ") -> 1С сч 90.01 убрать НДС! | B4: =IFERROR(__xludf.DUMMYFUNCTION("iferror(filter('Статьи'!$A$1:$A182,'Статьи'!$B$1:$B182=$B$3))"),"Выручка от аренды машиноместа") -> Выручка от аренды машиноместа | I4: =SUM(C4:H4) -> 0 | P4: =SUM(J4:K4) -> 0 | Q4: =I4-P4 -> 0 | R4: =IFERROR(I4/P4,0) -> 0 | S4: =IF(Q4=0,"",IF(R4=0,"обратить внимание",IF(R4>1,"выполнение","план не выполнен")))
A5: =IFERROR(VLOOKUP(B5,'Статьи'!$A$2:C27,3,0)," ") -> 1С сч 90.01 убрать НДС! | B5: =IFERROR(__xludf.DUMMYFUNCTION("""COMPUTED_VALUE"""),"Выручка за грузоперевозки") -> Выручка за грузоперевозки | I5: =SUM(C5:H5) -> 0 | P5: =SUM(J5:K5) -> 0 | Q5: =I5-P5 -> 0 | R5: =IFERROR(I5/P5,0) -> 0 | S5: =IF(Q5=0,"",IF(R5=0,"обратить внимание",IF(R5>1,"выполнение","план не выполнен")))
A6: =IFERROR(VLOOKUP(B6,'Статьи'!$A$2:C28,3,0)," ") | I6: =SUM(C6:H6) -> 0 | P6: =SUM(F6:J6) -> 0 | Q6: =I6-P6 -> 0 | R6: =IFERROR(I6/P6,0) -> 0 | S6: =IF(Q6=0,"",IF(R6=0,"обратить внимание",IF(R6>1,"выполнение","план не выполнен")))
A7: =IFERROR(VLOOKUP(B7,'Статьи'!$A$2:C29,3,0)," ") | I7: =SUM(C7:H7) -> 0 | P7: =SUM(F7:J7) -> 0 | Q7: =I7-P7 -> 0 | R7: =IFERROR(I7/P7,0) -> 0 | S7: =IF(Q7=0,"",IF(R7=0,"обратить внимание",IF(R7>1,"выполнение","план не выполнен")))
A8: =IFERROR(VLOOKUP(B8,'Статьи'!$A$2:C30,3,0)," ") | I8: =SUM(C8:H8) -> 0 | P8: =SUM(F8:J8) -> 0 | Q8: =I8-P8 -> 0 | R8: =IFERROR(I8/P8,0) -> 0 | S8: =IF(Q8=0,"",IF(R8=0,"обратить внимание",IF(R8>1,"выполнение","план не выполнен")))
A9: =IFERROR(VLOOKUP(B9,'Статьи'!$A$2:C31,3,0)," ") | Q9: =I9-P9 -> 0 | R9: =IFERROR(I9/P9,0) -> 0 | S9: =IF(Q9=0,"",IF(R9=0,"обратить внимание",IF(R9>1,"выполнение","план не выполнен")))
A10: =IFERROR(VLOOKUP(B10,'Статьи'!$A$2:C32,3,0)," ") | Q10: =I10-P10 -> 0 | R10: =IFERROR(I10/P10,0) -> 0 | S10: =IF(Q10=0,"",IF(R10=0,"обратить внимание",IF(R10>1,"выполнение","план не выполнен")))
B11: Производственные расходы | C11: =C12+C58 -> 0 | D11: =D12+D58 -> 0 | E11: =E12+E58 -> 0 | F11: =F12+F58 -> 0 | G11: =G12+G58 -> 0 | H11: =H12+H58 -> 0 | I11: =I12+I58 -> 0 | J11: =J12+J58 -> 0 | K11: =K12+K58 -> 0 | P11: =P12+P58 -> 0 | Q11: =I11-P11 -> 0 | R11: =IFERROR(I11/P11,0) -> 0 | S11: =IF(Q11=0,"",IF(R11>1,"план не выполнен","выполнение"))
B12: Переменные | C12: =sum(C13:C54) -> 0 | D12: =sum(D13:D54) -> 0 | E12: =sum(E13:E54) -> 0 | F12: =sum(F13:F54) -> 0 | G12: =sum(G13:G54) -> 0 | H12: =sum(H13:H54) -> 0 | I12: =sum(I13:I54) -> 0 | J12: =sum(J13:J54) -> 0 | K12: =sum(K13:K54) -> 0 | P12: =sum(P13:P54) -> 0 | Q12: =I12-P12 -> 0 | R12: =IFERROR(I12/P12,0) -> 0 | S12: =IF(Q12=0,"",IF(R12=0,"обратить внимание",IF(R12>1,"перерасход","экономия")))
A13: =IFERROR(VLOOKUP(B13,'Статьи'!$A$2:C35,3,0)," ") -> ДДС отчетного месяца. Без НДС! | B13: =IFERROR(__xludf.DUMMYFUNCTION("iferror(filter('Статьи'!$A$1:$A182,'Статьи'!$B$1:$B182=$B$12))"),"Комиссия топливных компаний") -> Комиссия топливных компаний | I13: =sum(C13:H13) -> 0 | P13: =SUM(J13:K13) -> 0 | Q13: =I13-P13 -> 0 | R13: =IFERROR(I13/P13,0) -> 0 | S13: =IF(Q13=0,"",IF(R13=0,"обратить внимание",IF(R13>1,"перерасход","экономия")))
A14: =IFERROR(VLOOKUP(B14,'Статьи'!$A$2:C36,3,0)," ") -> 1С | B14: =IFERROR(__xludf.DUMMYFUNCTION("""COMPUTED_VALUE"""),"Топливо для грузовых авто ") -> Топливо для грузовых авто | I14: =sum(C14:H14) -> 0 | P14: =SUM(J14:K14) -> 0 | Q14: =I14-P14 -> 0 | R14: =IFERROR(I14/P14,0) -> 0 | S14: =IF(Q14=0,"",IF(R14=0,"обратить внимание",IF(R14>1,"перерасход","экономия")))
A15: =IFERROR(VLOOKUP(B15,'Статьи'!$A$2:C37,3,0)," ") | I15: =sum(C15:H15) -> 0 | P15: =SUM(J15:K15) -> 0 | Q15: =I15-P15 -> 0 | R15: =IFERROR(I15/P15,0) -> 0 | S15: =IF(Q15=0,"",IF(R15=0,"обратить внимание",IF(R15>1,"перерасход","экономия")))
A16: =IFERROR(VLOOKUP(B16,'Статьи'!$A$2:C38,3,0)," ") | I16: =sum(C16:H16) -> 0 | P16: =SUM(J16:K16) -> 0 | Q16: =I16-P16 -> 0 | R16: =IFERROR(I16/P16,0) -> 0 | S16: =IF(Q16=0,"",IF(R16=0,"обратить внимание",IF(R16>1,"перерасход","экономия")))
A17: =IFERROR(VLOOKUP(B17,'Статьи'!$A$2:C39,3,0)," ") | I17: =sum(C17:H17) -> 0 | P17: =sum(F17:J17) -> 0 | Q17: =I17-P17 -> 0 | R17: =IFERROR(I17/P17,0) -> 0 | S17: =IF(Q17=0,"",IF(R17=0,"обратить внимание",IF(R17>1,"перерасход","экономия")))
I18: =sum(C18:H18) -> 0 | P18: =sum(F18:J18) -> 0 | Q18: =I18-P18 -> 0 | R18: =IFERROR(I18/P18,0) -> 0 | S18: =IF(Q18=0,0,IF(R18>1,"перерасход","экономия")) -> 0
I19: =sum(C19:H19) -> 0 | P19: =sum(F19:J19) -> 0 | Q19: =I19-P19 -> 0 | R19: =IFERROR(I19/P19,0) -> 0 | S19: =IF(Q19=0,0,IF(R19>1,"перерасход","экономия")) -> 0
I20: =sum(C20:H20) -> 0 | P20: =sum(F20:J20) -> 0 | Q20: =I20-P20 -> 0 | R20: =IFERROR(I20/P20,0) -> 0 | S20: =IF(Q20=0,0,IF(R20>1,"перерасход","экономия")) -> 0
I21: =sum(C21:H21) -> 0 | P21: =sum(F21:J21) -> 0 | Q21: =I21-P21 -> 0 | R21: =IFERROR(I21/P21,0) -> 0 | S21: =IF(Q21=0,0,IF(R21>1,"перерасход","экономия")) -> 0
I22: =sum(C22:H22) -> 0 | P22: =sum(F22:J22) -> 0 | Q22: =I22-P22 -> 0 | R22: =IFERROR(I22/P22,0) -> 0 | S22: =IF(Q22=0,0,IF(R22>1,"перерасход","экономия")) -> 0
I23: =sum(C23:H23) -> 0 | P23: =sum(F23:J23) -> 0 | Q23: =I23-P23 -> 0 | R23: =IFERROR(I23/P23,0) -> 0 | S23: =IF(Q23=0,0,IF(R23>1,"перерасход","экономия")) -> 0
I24: =sum(C24:H24) -> 0 | P24: =sum(F24:J24) -> 0 | Q24: =I24-P24 -> 0 | R24: =IFERROR(I24/P24,0) -> 0 | S24: =IF(Q24=0,0,IF(R24>1,"перерасход","экономия")) -> 0
I25: =sum(C25:H25) -> 0 | P25: =sum(F25:J25) -> 0 | Q25: =I25-P25 -> 0 | R25: =IFERROR(I25/P25,0) -> 0 | S25: =IF(Q25=0,0,IF(R25>1,"перерасход","экономия")) -> 0
I26: =sum(C26:H26) -> 0 | P26: =sum(F26:J26) -> 0 | Q26: =I26-P26 -> 0 | R26: =IFERROR(I26/P26,0) -> 0 | S26: =IF(Q26=0,0,IF(R26>1,"перерасход","экономия")) -> 0
I27: =sum(C27:H27) -> 0 | P27: =sum(F27:J27) -> 0 | Q27: =I27-P27 -> 0 | R27: =IFERROR(I27/P27,0) -> 0 | S27: =IF(Q27=0,0,IF(R27>1,"перерасход","экономия")) -> 0
I28: =sum(C28:H28) -> 0 | P28: =sum(F28:J28) -> 0 | Q28: =I28-P28 -> 0 | R28: =IFERROR(I28/P28,0) -> 0 | S28: =IF(Q28=0,0,IF(R28>1,"перерасход","экономия")) -> 0
I29: =sum(C29:H29) -> 0 | P29: =sum(F29:J29) -> 0 | Q29: =I29-P29 -> 0 | R29: =IFERROR(I29/P29,0) -> 0 | S29: =IF(Q29=0,0,IF(R29>1,"перерасход","экономия")) -> 0
... I54: =sum(C54:H54) -> 0 | P54: =sum(F54:J54) -> 0 | Q54: =I54-P54 -> 0 | R54: =IFERROR(I54/P54,0) -> 0 | S54: =IF(Q54=0,0,IF(R54>1,"перерасход","экономия")) -> 0
B55: Маржинальный доход | C55: =C3+C12 -> 0 | D55: =D3+D12 -> 0 | E55: =E3+E12 -> 0 | F55: =F3+F12 -> 0 | G55: =G3+G12 -> 0 | H55: =H3+H12 -> 0 | I55: =I3+I12 -> 0 | J55: =J3+J12 -> 0 | K55: =K3+K12 -> 0 | P55: =P3+P12 -> 0 | Q55: =I55-P55 -> 0 | R55: =IFERROR(I55/P55,0) -> 0 | S55: =IF(Q55=0,"",IF(R55>1,"выполнение","план не выполнен"))
B56: Рентабельность по марже | C56: =IFERROR(C55/C$3,"") | D56: =IFERROR(D55/D$3,"") | E56: =IFERROR(E55/E$3,"") | F56: =IFERROR(F55/F$3,"") | G56: =IFERROR(G55/G$3,"") | H56: =IFERROR(H55/H$3,"") | I56: =IFERROR(I55/I$3,"") | J56: =IFERROR(J55/J$3,"") | K56: =IFERROR(K55/K$3,"") | P56: =IFERROR(P55/P$3,"")
B58: Общепроизводственные | C58: =sum(C59:C79) -> 0 | D58: =sum(D59:D79) -> 0 | E58: =sum(E59:E79) -> 0 | F58: =sum(F59:F79) -> 0 | G58: =sum(G59:G79) -> 0 | H58: =sum(H59:H79) -> 0 | I58: =SUM(I59:I84) -> 0 | J58: =SUM(J59:J84) -> 0 | K58: =SUM(K59:K84) -> 0 | P58: =SUM(P59:P84) -> 0 | Q58: =I58-P58 -> 0 | R58: =IFERROR(I58/P58,0) -> 0 | S58: =IF(Q58=0,"",IF(R58>1,"план не выполнен","выполнение"))
A59: =IFERROR(VLOOKUP(B59,'Статьи'!$A$2:C81,3,0)," ") -> 1С | B59: =IFERROR(__xludf.DUMMYFUNCTION("iferror(filter('Статьи'!$A$1:$A182,'Статьи'!$B$1:$B182=$B$58))"),"Зарплата производственного персонала") -> Зарплата производственного персонала | I59: =SUM(C59:H59) -> 0 | P59: =SUM(J59:K59) -> 0 | Q59: =I59-P59 -> 0 | R59: =IFERROR(I59/P59,0) -> 0 | S59: =IF(Q59=0,"",IF(R59=0,"обратить внимание",IF(R59>1,"перерасход","экономия")))
A60: =IFERROR(VLOOKUP(B60,'Статьи'!$A$2:C82,3,0)," ") -> ДДС отчетного месяца. Без НДС! | B60: =IFERROR(__xludf.DUMMYFUNCTION("""COMPUTED_VALUE"""),"Таможенные расходы") -> Таможенные расходы | I60: =SUM(C60:H60) -> 0 | P60: =SUM(J60:K60) -> 0 | Q60: =I60-P60 -> 0 | R60: =IFERROR(I60/P60,0) -> 0 | S60: =IF(Q60=0,"",IF(R60=0,"обратить внимание",IF(R60>1,"перерасход","экономия")))
A61: =IFERROR(VLOOKUP(B61,'Статьи'!$A$2:C83,3,0)," ") | I61: =SUM(C61:H61) -> 0 | P61: =SUM(J61:K61) -> 0 | Q61: =I61-P61 -> 0 | R61: =IFERROR(I61/P61,0) -> 0 | S61: =IF(Q61=0,"",IF(R61=0,"обратить внимание",IF(R61>1,"перерасход","экономия")))
A62: =IFERROR(VLOOKUP(B62,'Статьи'!$A$2:C84,3,0)," ") | I62: =SUM(C62:H62) -> 0 | P62: =SUM(J62:K62) -> 0 | Q62: =I62-P62 -> 0 | R62: =IFERROR(I62/P62,0) -> 0 | S62: =IF(Q62=0,"",IF(R62=0,"обратить внимание",IF(R62>1,"перерасход","экономия")))
A63: =IFERROR(VLOOKUP(B63,'Статьи'!$A$2:C85,3,0)," ") | I63: =SUM(C63:H63) -> 0 | P63: =SUM(J63:K63) -> 0 | Q63: =I63-P63 -> 0 | R63: =IFERROR(I63/P63,0) -> 0 | S63: =IF(Q63=0,"",IF(R63=0,"обратить внимание",IF(R63>1,"перерасход","экономия")))
A64: =IFERROR(VLOOKUP(B64,'Статьи'!$A$2:C86,3,0)," ") | I64: =SUM(C64:H64) -> 0 | P64: =SUM(J64:K64) -> 0 | Q64: =I64-P64 -> 0 | R64: =IFERROR(I64/P64,0) -> 0 | S64: =IF(Q64=0,"",IF(R64=0,"обратить внимание",IF(R64>1,"перерасход","экономия")))
A65: =IFERROR(VLOOKUP(B65,'Статьи'!$A$2:C87,3,0)," ") | I65: =SUM(C65:H65) -> 0 | P65: =SUM(J65:K65) -> 0 | Q65: =I65-P65 -> 0 | R65: =IFERROR(I65/P65,0) -> 0 | S65: =IF(Q65=0,"",IF(R65=0,"обратить внимание",IF(R65>1,"перерасход","экономия")))
...

Sheet 3
C1: ФАКТ | J1: План | Q1: Отклонения
A2: Источники | C2: {=TRANSPOSE('Справочник'!D2:D7)} -> ООО "Весело живем" | D2: ООО "Некогда грустить" | E2: 3 | F2: 4 | G2: 5 | H2: 6 | I2: Итого | J2: {=TRANSPOSE('Справочник'!D2:D7)} -> ООО "Весело живем" | K2: ООО "Некогда грустить" | L2: 3 | M2: 4 | N2: 5 | O2: 6 | P2: Итого | Q2: факт-план, руб | R2: факт/план, % | S2: Результат
B3: Выручка | C3: =SUM(C4:C10) -> 0 | D3: =SUM(D4:D10) -> 0 | E3: =SUM(E4:E10) -> 0 | F3: =SUM(F4:F10) -> 0 | G3: =SUM(G4:G10) -> 0 | H3: =SUM(H4:H10) -> 0 | I3: =sum(C3:H3) -> 0 | J3: =SUM(J4:J10) -> 0 | K3: =SUM(K4:K10) -> 0 | P3: =SUM(P4:P10) -> 0 | Q3: =I3-P3 -> 0 | R3: =IFERROR(I3/P3,0) -> 0 | S3: =IF(Q3=0,"",IF(R3>1,"выполнение","план не выполнен"))
A4: =IFERROR(VLOOKUP(B4,'Статьи'!$A$2:C26,3,0)," ") -> 1С сч 90.01 убрать НДС! | B4: =IFERROR(__xludf.DUMMYFUNCTION("iferror(filter('Статьи'!$A$1:$A182,'Статьи'!$B$1:$B182=$B$3))"),"Выручка от аренды машиноместа") -> Выручка от аренды машиноместа | I4: =SUM(C4:H4) -> 0 | P4: =SUM(J4:K4) -> 0 | Q4: =I4-P4 -> 0 | R4: =IFERROR(I4/P4,0) -> 0 | S4: =IF(Q4=0,"",IF(R4=0,"обратить внимание",IF(R4>1,"выполнение","план не выполнен")))
A5: =IFERROR(VLOOKUP(B5,'Статьи'!$A$2:C27,3,0)," ") -> 1С сч 90.01 убрать НДС! | B5: =IFERROR(__xludf.DUMMYFUNCTION("""COMPUTED_VALUE"""),"Выручка за грузоперевозки") -> Выручка за грузоперевозки | I5: =SUM(C5:H5) -> 0 | P5: =SUM(J5:K5) -> 0 | Q5: =I5-P5 -> 0 | R5: =IFERROR(I5/P5,0) -> 0 | S5: =IF(Q5=0,"",IF(R5=0,"обратить внимание",IF(R5>1,"выполнение","план не выполнен")))
A6: =IFERROR(VLOOKUP(B6,'Статьи'!$A$2:C28,3,0)," ") | I6: =SUM(C6:H6) -> 0 | P6: =SUM(F6:J6) -> 0 | Q6: =I6-P6 -> 0 | R6: =IFERROR(I6/P6,0) -> 0 | S6: =IF(Q6=0,"",IF(R6=0,"обратить внимание",IF(R6>1,"выполнение","план не выполнен")))
A7: =IFERROR(VLOOKUP(B7,'Статьи'!$A$2:C29,3,0)," ") | I7: =SUM(C7:H7) -> 0 | P7: =SUM(F7:J7) -> 0 | Q7: =I7-P7 -> 0 | R7: =IFERROR(I7/P7,0) -> 0 | S7: =IF(Q7=0,"",IF(R7=0,"обратить внимание",IF(R7>1,"выполнение","план не выполнен")))
A8: =IFERROR(VLOOKUP(B8,'Статьи'!$A$2:C30,3,0)," ") | I8: =SUM(C8:H8) -> 0 | P8: =SUM(F8:J8) -> 0 | Q8: =I8-P8 -> 0 | R8: =IFERROR(I8/P8,0) -> 0 | S8: =IF(Q8=0,"",IF(R8=0,"обратить внимание",IF(R8>1,"выполнение","план не выполнен")))
A9: =IFERROR(VLOOKUP(B9,'Статьи'!$A$2:C31,3,0)," ") | Q9: =I9-P9 -> 0 | R9: =IFERROR(I9/P9,0) -> 0 | S9: =IF(Q9=0,"",IF(R9=0,"обратить внимание",IF(R9>1,"выполнение","план не выполнен")))
A10: =IFERROR(VLOOKUP(B10,'Статьи'!$A$2:C32,3,0)," ") | Q10: =I10-P10 -> 0 | R10: =IFERROR(I10/P10,0) -> 0 | S10: =IF(Q10=0,"",IF(R10=0,"обратить внимание",IF(R10>1,"выполнение","план не выполнен")))
B11: Производственные расходы | C11: =C12+C58 -> 0 | D11: =D12+D58 -> 0 | E11: =E12+E58 -> 0 | F11: =F12+F58 -> 0 | G11: =G12+G58 -> 0 | H11: =H12+H58 -> 0 | I11: =I12+I58 -> 0 | J11: =J12+J58 -> 0 | K11: =K12+K58 -> 0 | P11: =P12+P58 -> 0 | Q11: =I11-P11 -> 0 | R11: =IFERROR(I11/P11,0) -> 0 | S11: =IF(Q11=0,"",IF(R11>1,"план не выполнен","выполнение"))
B12: Переменные | C12: =sum(C13:C54) -> 0 | D12: =sum(D13:D54) -> 0 | E12: =sum(E13:E54) -> 0 | F12: =sum(F13:F54) -> 0 | G12: =sum(G13:G54) -> 0 | H12: =sum(H13:H54) -> 0 | I12: =sum(I13:I54) -> 0 | J12: =sum(J13:J54) -> 0 | K12: =sum(K13:K54) -> 0 | P12: =sum(P13:P54) -> 0 | Q12: =I12-P12 -> 0 | R12: =IFERROR(I12/P12,0) -> 0 | S12: =IF(Q12=0,"",IF(R12=0,"обратить внимание",IF(R12>1,"перерасход","экономия")))
A13: =IFERROR(VLOOKUP(B13,'Статьи'!$A$2:C35,3,0)," ") -> ДДС отчетного месяца. Без НДС! | B13: =IFERROR(__xludf.DUMMYFUNCTION("iferror(filter('Статьи'!$A$1:$A182,'Статьи'!$B$1:$B182=$B$12))"),"Комиссия топливных компаний") -> Комиссия топливных компаний | I13: =sum(C13:H13) -> 0 | P13: =SUM(J13:K13) -> 0 | Q13: =I13-P13 -> 0 | R13: =IFERROR(I13/P13,0) -> 0 | S13: =IF(Q13=0,"",IF(R13=0,"обратить внимание",IF(R13>1,"перерасход","экономия")))
A14: =IFERROR(VLOOKUP(B14,'Статьи'!$A$2:C36,3,0)," ") -> 1С | B14: =IFERROR(__xludf.DUMMYFUNCTION("""COMPUTED_VALUE"""),"Топливо для грузовых авто ") -> Топливо для грузовых авто | I14: =sum(C14:H14) -> 0 | P14: =SUM(J14:K14) -> 0 | Q14: =I14-P14 -> 0 | R14: =IFERROR(I14/P14,0) -> 0 | S14: =IF(Q14=0,"",IF(R14=0,"обратить внимание",IF(R14>1,"перерасход","экономия")))
A15: =IFERROR(VLOOKUP(B15,'Статьи'!$A$2:C37,3,0)," ") | I15: =sum(C15:H15) -> 0 | P15: =SUM(J15:K15) -> 0 | Q15: =I15-P15 -> 0 | R15: =IFERROR(I15/P15,0) -> 0 | S15: =IF(Q15=0,"",IF(R15=0,"обратить внимание",IF(R15>1,"перерасход","экономия")))
A16: =IFERROR(VLOOKUP(B16,'Статьи'!$A$2:C38,3,0)," ") | I16: =sum(C16:H16) -> 0 | P16: =SUM(J16:K16) -> 0 | Q16: =I16-P16 -> 0 | R16: =IFERROR(I16/P16,0) -> 0 | S16: =IF(Q16=0,"",IF(R16=0,"обратить внимание",IF(R16>1,"перерасход","экономия")))
A17: =IFERROR(VLOOKUP(B17,'Статьи'!$A$2:C39,3,0)," ") | I17: =sum(C17:H17) -> 0 | P17: =sum(F17:J17) -> 0 | Q17: =I17-P17 -> 0 | R17: =IFERROR(I17/P17,0) -> 0 | S17: =IF(Q17=0,"",IF(R17=0,"обратить внимание",IF(R17>1,"перерасход","экономия")))
I18: =sum(C18:H18) -> 0 | P18: =sum(F18:J18) -> 0 | Q18: =I18-P18 -> 0 | R18: =IFERROR(I18/P18,0) -> 0 | S18: =IF(Q18=0,0,IF(R18>1,"перерасход","экономия")) -> 0
I19: =sum(C19:H19) -> 0 | P19: =sum(F19:J19) -> 0 | Q19: =I19-P19 -> 0 | R19: =IFERROR(I19/P19,0) -> 0 | S19: =IF(Q19=0,0,IF(R19>1,"перерасход","экономия")) -> 0
I20: =sum(C20:H20) -> 0 | P20: =sum(F20:J20) -> 0 | Q20: =I20-P20 -> 0 | R20: =IFERROR(I20/P20,0) -> 0 | S20: =IF(Q20=0,0,IF(R20>1,"перерасход","экономия")) -> 0
I21: =sum(C21:H21) -> 0 | P21: =sum(F21:J21) -> 0 | Q21: =I21-P21 -> 0 | R21: =IFERROR(I21/P21,0) -> 0 | S21: =IF(Q21=0,0,IF(R21>1,"перерасход","экономия")) -> 0
I22: =sum(C22:H22) -> 0 | P22: =sum(F22:J22) -> 0 | Q22: =I22-P22 -> 0 | R22: =IFERROR(I22/P22,0) -> 0 | S22: =IF(Q22=0,0,IF(R22>1,"перерасход","экономия")) -> 0
I23: =sum(C23:H23) -> 0 | P23: =sum(F23:J23) -> 0 | Q23: =I23-P23 -> 0 | R23: =IFERROR(I23/P23,0) -> 0 | S23: =IF(Q23=0,0,IF(R23>1,"перерасход","экономия")) -> 0
I24: =sum(C24:H24) -> 0 | P24: =sum(F24:J24) -> 0 | Q24: =I24-P24 -> 0 | R24: =IFERROR(I24/P24,0) -> 0 | S24: =IF(Q24=0,0,IF(R24>1,"перерасход","экономия")) -> 0
I25: =sum(C25:H25) -> 0 | P25: =sum(F25:J25) -> 0 | Q25: =I25-P25 -> 0 | R25: =IFERROR(I25/P25,0) -> 0 | S25: =IF(Q25=0,0,IF(R25>1,"перерасход","экономия")) -> 0
I26: =sum(C26:H26) -> 0 | P26: =sum(F26:J26) -> 0 | Q26: =I26-P26 -> 0 | R26: =IFERROR(I26/P26,0) -> 0 | S26: =IF(Q26=0,0,IF(R26>1,"перерасход","экономия")) -> 0
I27: =sum(C27:H27) -> 0 | P27: =sum(F27:J27) -> 0 | Q27: =I27-P27 -> 0 | R27: =IFERROR(I27/P27,0) -> 0 | S27: =IF(Q27=0,0,IF(R27>1,"перерасход","экономия")) -> 0
I28: =sum(C28:H28) -> 0 | P28: =sum(F28:J28) -> 0 | Q28: =I28-P28 -> 0 | R28: =IFERROR(I28/P28,0) -> 0 | S28: =IF(Q28=0,0,IF(R28>1,"перерасход","экономия")) -> 0
I29: =sum(C29:H29) -> 0 | P29: =sum(F29:J29) -> 0 | Q29: =I29-P29 -> 0 | R29: =IFERROR(I29/P29,0) -> 0 | S29: =IF(Q29=0,0,IF(R29>1,"перерасход","экономия")) -> 0
... I54: =sum(C54:H54) -> 0 | P54: =sum(F54:J54) -> 0 | Q54: =I54-P54 -> 0 | R54: =IFERROR(I54/P54,0) -> 0 | S54: =IF(Q54=0,0,IF(R54>1,"перерасход","экономия")) -> 0
B55: Маржинальный доход | C55: =C3+C12 -> 0 | D55: =D3+D12 -> 0 | E55: =E3+E12 -> 0 | F55: =F3+F12 -> 0 | G55: =G3+G12 -> 0 | H55: =H3+H12 -> 0 | I55: =I3+I12 -> 0 | J55: =J3+J12 -> 0 | K55: =K3+K12 -> 0 | P55: =P3+P12 -> 0 | Q55: =I55-P55 -> 0 | R55: =IFERROR(I55/P55,0) -> 0 | S55: =IF(Q55=0,"",IF(R55>1,"выполнение","план не выполнен"))
B56: Рентабельность по марже | C56: =IFERROR(C55/C$3,"") | D56: =IFERROR(D55/D$3,"") | E56: =IFERROR(E55/E$3,"") | F56: =IFERROR(F55/F$3,"") | G56: =IFERROR(G55/G$3,"") | H56: =IFERROR(H55/H$3,"") | I56: =IFERROR(I55/I$3,"") | J56: =IFERROR(J55/J$3,"") | K56: =IFERROR(K55/K$3,"") | P56: =IFERROR(P55/P$3,"")
B58: Общепроизводственные | C58: =sum(C59:C79) -> 0 | D58: =sum(D59:D79) -> 0 | E58: =sum(E59:E79) -> 0 | F58: =sum(F59:F79) -> 0 | G58: =sum(G59:G79) -> 0 | H58: =sum(H59:H79) -> 0 | I58: =SUM(I59:I84) -> 0 | J58: =SUM(J59:J84) -> 0 | K58: =SUM(K59:K84) -> 0 | P58: =SUM(P59:P84) -> 0 | Q58: =I58-P58 -> 0 | R58: =IFERROR(I58/P58,0) -> 0 | S58: =IF(Q58=0,"",IF(R58>1,"план не выполнен","выполнение"))
A59: =IFERROR(VLOOKUP(B59,'Статьи'!$A$2:C81,3,0)," ") -> 1С | B59: =IFERROR(__xludf.DUMMYFUNCTION("iferror(filter('Статьи'!$A$1:$A182,'Статьи'!$B$1:$B182=$B$58))"),"Зарплата производственного персонала") -> Зарплата производственного персонала | I59: =SUM(C59:H59) -> 0 | P59: =SUM(J59:K59) -> 0 | Q59: =I59-P59 -> 0 | R59: =IFERROR(I59/P59,0) -> 0 | S59: =IF(Q59=0,"",IF(R59=0,"обратить внимание",IF(R59>1,"перерасход","экономия")))
A60: =IFERROR(VLOOKUP(B60,'Статьи'!$A$2:C82,3,0)," ") -> ДДС отчетного месяца. Без НДС! | B60: =IFERROR(__xludf.DUMMYFUNCTION("""COMPUTED_VALUE"""),"Таможенные расходы") -> Таможенные расходы | I60: =SUM(C60:H60) -> 0 | P60: =SUM(J60:K60) -> 0 | Q60: =I60-P60 -> 0 | R60: =IFERROR(I60/P60,0) -> 0 | S60: =IF(Q60=0,"",IF(R60=0,"обратить внимание",IF(R60>1,"перерасход","экономия")))
A61: =IFERROR(VLOOKUP(B61,'Статьи'!$A$2:C83,3,0)," ") | I61: =SUM(C61:H61) -> 0 | P61: =SUM(J61:K61) -> 0 | Q61: =I61-P61 -> 0 | R61: =IFERROR(I61/P61,0) -> 0 | S61: =IF(Q61=0,"",IF(R61=0,"обратить внимание",IF(R61>1,"перерасход","экономия")))
A62: =IFERROR(VLOOKUP(B62,'Статьи'!$A$2:C84,3,0)," ") | I62: =SUM(C62:H62) -> 0 | P62: =SUM(J62:K62) -> 0 | Q62: =I62-P62 -> 0 | R62: =IFERROR(I62/P62,0) -> 0 | S62: =IF(Q62=0,"",IF(R62=0,"обратить внимание",IF(R62>1,"перерасход","экономия")))
A63: =IFERROR(VLOOKUP(B63,'Статьи'!$A$2:C85,3,0)," ") | I63: =SUM(C63:H63) -> 0 | P63: =SUM(J63:K63) -> 0 | Q63: =I63-P63 -> 0 | R63: =IFERROR(I63/P63,0) -> 0 | S63: =IF(Q63=0,"",IF(R63=0,"обратить внимание",IF(R63>1,"перерасход","экономия")))
A64: =IFERROR(VLOOKUP(B64,'Статьи'!$A$2:C86,3,0)," ") | I64: =SUM(C64:H64) -> 0 | P64: =SUM(J64:K64) -> 0 | Q64: =I64-P64 -> 0 | R64: =IFERROR(I64/P64,0) -> 0 | S64: =IF(Q64=0,"",IF(R64=0,"обратить внимание",IF(R64>1,"перерасход","экономия")))
A65: =IFERROR(VLOOKUP(B65,'Статьи'!$A$2:C87,3,0)," ") | I65: =SUM(C65:H65) -> 0 | P65: =SUM(J65:K65) -> 0 | Q65: =I65-P65 -> 0 | R65: =IFERROR(I65/P65,0) -> 0 | S65: =IF(Q65=0,"",IF(R65=0,"обратить внимание",IF(R65>1,"перерасход","экономия")))
...

Sheet 4
C1: ФАКТ | J1: План | Q1: Отклонения
A2: Источники | C2: {=TRANSPOSE('Справочник'!D2:D7)} -> ООО "Весело живем" | D2: ООО "Некогда грустить" | E2: 3 | F2: 4 | G2: 5 | H2: 6 | I2: Итого | J2: {=TRANSPOSE('Справочник'!D2:D7)} -> ООО "Весело живем" | K2: ООО "Некогда грустить" | L2: 3 | M2: 4 | N2: 5 | O2: 6 | P2: Итого | Q2: факт-план, EUR | R2: факт/план, % | S2: Результат
B3: Выручка | C3: =SUM(C4:C10) -> 4 | D3: =SUM(D4:D10) -> 0 | E3: =SUM(E4:E10) -> 0 | F3: =SUM(F4:F10) -> 0 | G3: =SUM(G4:G10) -> 0 | H3: =SUM(H4:H10) -> 0 | I3: =sum(C3:H3) -> 4 | J3: =SUM(J4:J10) -> 0 | K3: =SUM(K4:K10) -> 0 | P3: =SUM(P4:P10) -> 0 | Q3: =I3-P3 -> 4 | R3: =IFERROR(I3/P3,0) -> 0 | S3: =IF(Q3=0,"",IF(R3>1,"выполнение","план не выполнен")) -> план не выполнен
A4: =IFERROR(VLOOKUP(B4,'Статьи'!$A$2:C26,3,0)," ") -> 1С сч 90.01 убрать НДС! | B4: =IFERROR(__xludf.DUMMYFUNCTION("iferror(filter('Статьи'!$A$1:$A177,'Статьи'!$B$1:$B177=$B$3))"),"Выручка от аренды машиноместа") -> Выручка от аренды машиноместа | C4: 4 | I4: =SUM(C4:H4) -> 4 | P4: =SUM(J4:K4) -> 0 | Q4: =I4-P4 -> 4 | R4: =IFERROR(I4/P4,0) -> 0 | S4: =IF(Q4=0,"",IF(R4=0,"обратить внимание",IF(R4>1,"выполнение","план не выполнен"))) -> обратить внимание
A5: =IFERROR(VLOOKUP(B5,'Статьи'!$A$2:C27,3,0)," ") -> 1С сч 90.01 убрать НДС! | B5: =IFERROR(__xludf.DUMMYFUNCTION("""COMPUTED_VALUE"""),"Выручка за грузоперевозки") -> Выручка за грузоперевозки | I5: =SUM(C5:H5) -> 0 | P5: =SUM(J5:K5) -> 0 | Q5: =I5-P5 -> 0 | R5: =IFERROR(I5/P5,0) -> 0 | S5: =IF(Q5=0,"",IF(R5=0,"обратить внимание",IF(R5>1,"выполнение","план не выполнен")))
A6: =IFERROR(VLOOKUP(B6,'Статьи'!$A$2:C28,3,0)," ") | I6: =SUM(C6:H6) -> 0 | P6: =SUM(F6:J6) -> 0 | Q6: =I6-P6 -> 0 | R6: =IFERROR(I6/P6,0) -> 0 | S6: =IF(Q6=0,"",IF(R6=0,"обратить внимание",IF(R6>1,"выполнение","план не выполнен")))
A7: =IFERROR(VLOOKUP(B7,'Статьи'!$A$2:C29,3,0)," ") | I7: =SUM(C7:H7) -> 0 | P7: =SUM(F7:J7) -> 0 | Q7: =I7-P7 -> 0 | R7: =IFERROR(I7/P7,0) -> 0 | S7: =IF(Q7=0,"",IF(R7=0,"обратить внимание",IF(R7>1,"выполнение","план не выполнен")))
A8: =IFERROR(VLOOKUP(B8,'Статьи'!$A$2:C30,3,0)," ") | I8: =SUM(C8:H8) -> 0 | P8: =SUM(F8:J8) -> 0 | Q8: =I8-P8 -> 0 | R8: =IFERROR(I8/P8,0) -> 0 | S8: =IF(Q8=0,"",IF(R8=0,"обратить внимание",IF(R8>1,"выполнение","план не выполнен")))
A9: =IFERROR(VLOOKUP(B9,'Статьи'!$A$2:C31,3,0)," ") | Q9: =I9-P9 -> 0 | R9: =IFERROR(I9/P9,0) -> 0 | S9: =IF(Q9=0,"",IF(R9=0,"обратить внимание",IF(R9>1,"выполнение","план не выполнен")))
A10: =IFERROR(VLOOKUP(B10,'Статьи'!$A$2:C32,3,0)," ") | Q10: =I10-P10 -> 0 | R10: =IFERROR(I10/P10,0) -> 0 | S10: =IF(Q10=0,"",IF(R10=0,"обратить внимание",IF(R10>1,"выполнение","план не выполнен")))
B11: Производственные расходы | C11: =C12+C58 -> 0 | D11: =D12+D58 -> 0 | E11: =E12+E58 -> 0 | F11: =F12+F58 -> 0 | G11: =G12+G58 -> 0 | H11: =H12+H58 -> 0 | I11: =I12+I58 -> 0 | J11: =J12+J58 -> 0 | K11: =K12+K58 -> 0 | P11: =P12+P58 -> 0 | Q11: =I11-P11 -> 0 | R11: =IFERROR(I11/P11,0) -> 0 | S11: =IF(Q11=0,"",IF(R11>1,"план не выполнен","выполнение"))
B12: Переменные | C12: =sum(C13:C54) -> 0 | D12: =sum(D13:D54) -> 0 | E12: =sum(E13:E54) -> 0 | F12: =sum(F13:F54) -> 0 | G12: =sum(G13:G54) -> 0 | H12: =sum(H13:H54) -> 0 | I12: =sum(I13:I54) -> 0 | J12: =sum(J13:J54) -> 0 | K12: =sum(K13:K54) -> 0 | P12: =sum(P13:P54) -> 0 | Q12: =I12-P12 -> 0 | R12: =IFERROR(I12/P12,0) -> 0 | S12: =IF(Q12=0,"",IF(R12=0,"обратить внимание",IF(R12>1,"перерасход","экономия")))
A13: =IFERROR(VLOOKUP(B13,'Статьи'!$A$2:C35,3,0)," ") -> ДДС отчетного месяца. Без НДС! | B13: =IFERROR(__xludf.DUMMYFUNCTION("iferror(filter('Статьи'!$A$1:$A177,'Статьи'!$B$1:$B177=$B$12))"),"Комиссия топливных компаний") -> Комиссия топливных компаний | I13: =sum(C13:H13) -> 0 | P13: =SUM(J13:K13) -> 0 | Q13: =I13-P13 -> 0 | R13: =IFERROR(I13/P13,0) -> 0 | S13: =IF(Q13=0,"",IF(R13=0,"обратить внимание",IF(R13>1,"перерасход","экономия")))
A14: =IFERROR(VLOOKUP(B14,'Статьи'!$A$2:C36,3,0)," ") -> 1С | B14: =IFERROR(__xludf.DUMMYFUNCTION("""COMPUTED_VALUE"""),"Топливо для грузовых авто ") -> Топливо для грузовых авто | I14: =sum(C14:H14) -> 0 | P14: =SUM(J14:K14) -> 0 | Q14: =I14-P14 -> 0 | R14: =IFERROR(I14/P14,0) -> 0 | S14: =IF(Q14=0,"",IF(R14=0,"обратить внимание",IF(R14>1,"перерасход","экономия")))
A15: =IFERROR(VLOOKUP(B15,'Статьи'!$A$2:C37,3,0)," ") | I15: =sum(C15:H15) -> 0 | P15: =SUM(J15:K15) -> 0 | Q15: =I15-P15 -> 0 | R15: =IFERROR(I15/P15,0) -> 0 | S15: =IF(Q15=0,"",IF(R15=0,"обратить внимание",IF(R15>1,"перерасход","экономия")))
A16: =IFERROR(VLOOKUP(B16,'Статьи'!$A$2:C38,3,0)," ") | I16: =sum(C16:H16) -> 0 | P16: =SUM(J16:K16) -> 0 | Q16: =I16-P16 -> 0 | R16: =IFERROR(I16/P16,0) -> 0 | S16: =IF(Q16=0,"",IF(R16=0,"обратить внимание",IF(R16>1,"перерасход","экономия")))
A17: =IFERROR(VLOOKUP(B17,'Статьи'!$A$2:C39,3,0)," ") | I17: =sum(C17:H17) -> 0 | P17: =sum(F17:J17) -> 0 | Q17: =I17-P17 -> 0 | R17: =IFERROR(I17/P17,0) -> 0 | S17: =IF(Q17=0,"",IF(R17=0,"обратить внимание",IF(R17>1,"перерасход","экономия")))
I18: =sum(C18:H18) -> 0 | P18: =sum(F18:J18) -> 0 | Q18: =I18-P18 -> 0 | R18: =IFERROR(I18/P18,0) -> 0 | S18: =IF(Q18=0,0,IF(R18>1,"перерасход","экономия")) -> 0
I19: =sum(C19:H19) -> 0 | P19: =sum(F19:J19) -> 0 | Q19: =I19-P19 -> 0 | R19: =IFERROR(I19/P19,0) -> 0 | S19: =IF(Q19=0,0,IF(R19>1,"перерасход","экономия")) -> 0
I20: =sum(C20:H20) -> 0 | P20: =sum(F20:J20) -> 0 | Q20: =I20-P20 -> 0 | R20: =IFERROR(I20/P20,0) -> 0 | S20: =IF(Q20=0,0,IF(R20>1,"перерасход","экономия")) -> 0
I21: =sum(C21:H21) -> 0 | P21: =sum(F21:J21) -> 0 | Q21: =I21-P21 -> 0 | R21: =IFERROR(I21/P21,0) -> 0 | S21: =IF(Q21=0,0,IF(R21>1,"перерасход","экономия")) -> 0
I22: =sum(C22:H22) -> 0 | P22: =sum(F22:J22) -> 0 | Q22: =I22-P22 -> 0 | R22: =IFERROR(I22/P22,0) -> 0 | S22: =IF(Q22=0,0,IF(R22>1,"перерасход","экономия")) -> 0
I23: =sum(C23:H23) -> 0 | P23: =sum(F23:J23) -> 0 | Q23: =I23-P23 -> 0 | R23: =IFERROR(I23/P23,0) -> 0 | S23: =IF(Q23=0,0,IF(R23>1,"перерасход","экономия")) -> 0
I24: =sum(C24:H24) -> 0 | P24: =sum(F24:J24) -> 0 | Q24: =I24-P24 -> 0 | R24: =IFERROR(I24/P24,0) -> 0 | S24: =IF(Q24=0,0,IF(R24>1,"перерасход","экономия")) -> 0
I25: =sum(C25:H25) -> 0 | P25: =sum(F25:J25) -> 0 | Q25: =I25-P25 -> 0 | R25: =IFERROR(I25/P25,0) -> 0 | S25: =IF(Q25=0,0,IF(R25>1,"перерасход","экономия")) -> 0
I26: =sum(C26:H26) -> 0 | P26: =sum(F26:J26) -> 0 | Q26: =I26-P26 -> 0 | R26: =IFERROR(I26/P26,0) -> 0 | S26: =IF(Q26=0,0,IF(R26>1,"перерасход","экономия")) -> 0
I27: =sum(C27:H27) -> 0 | P27: =sum(F27:J27) -> 0 | Q27: =I27-P27 -> 0 | R27: =IFERROR(I27/P27,0) -> 0 | S27: =IF(Q27=0,0,IF(R27>1,"перерасход","экономия")) -> 0
I28: =sum(C28:H28) -> 0 | P28: =sum(F28:J28) -> 0 | Q28: =I28-P28 -> 0 | R28: =IFERROR(I28/P28,0) -> 0 | S28: =IF(Q28=0,0,IF(R28>1,"перерасход","экономия")) -> 0
I29: =sum(C29:H29) -> 0 | P29: =sum(F29:J29) -> 0 | Q29: =I29-P29 -> 0 | R29: =IFERROR(I29/P29,0) -> 0 | S29: =IF(Q29=0,0,IF(R29>1,"перерасход","экономия")) -> 0
... I54: =sum(C54:H54) -> 0 | P54: =sum(F54:J54) -> 0 | Q54: =I54-P54 -> 0 | R54: =IFERROR(I54/P54,0) -> 0 | S54: =IF(Q54=0,0,IF(R54>1,"перерасход","экономия")) -> 0
B55: Маржинальный доход | C55: =C3+C12 -> 4 | D55: =D3+D12 -> 0 | E55: =E3+E12 -> 0 | F55: =F3+F12 -> 0 | G55: =G3+G12 -> 0 | H55: =H3+H12 -> 0 | I55: =I3+I12 -> 4 | J55: =J3+J12 -> 0 | K55: =K3+K12 -> 0 | P55: =P3+P12 -> 0 | Q55: =I55-P55 -> 4 | R55: =IFERROR(I55/P55,0) -> 0 | S55: =IF(Q55=0,"",IF(R55>1,"выполнение","план не выполнен")) -> план не выполнен
B56: Рентабельность по марже | C56: =IFERROR(C55/C$3,"") -> 1 | D56: =IFERROR(D55/D$3,"") | E56: =IFERROR(E55/E$3,"") | F56: =IFERROR(F55/F$3,"") | G56: =IFERROR(G55/G$3,"") | H56: =IFERROR(H55/H$3,"") | I56: =IFERROR(I55/I$3,"") -> 1 | J56: =IFERROR(J55/J$3,"") | K56: =IFERROR(K55/K$3,"") | P56: =IFERROR(P55/P$3,"")
B58: Общепроизводственные | C58: =sum(C59:C79) -> 0 | D58: =sum(D59:D79) -> 0 | E58: =sum(E59:E79) -> 0 | F58: =sum(F59:F79) -> 0 | G58: =sum(G59:G79) -> 0 | H58: =sum(H59:H79) -> 0 | I58: =SUM(I59:I84) -> 0 | J58: =SUM(J59:J84) -> 0 | K58: =SUM(K59:K84) -> 0 | P58: =SUM(P59:P84) -> 0 | Q58: =I58-P58 -> 0 | R58: =IFERROR(I58/P58,0) -> 0 | S58: =IF(Q58=0,"",IF(R58>1,"план не выполнен","выполнение"))
A59: =IFERROR(VLOOKUP(B59,'Статьи'!$A$2:C81,3,0)," ") -> 1С | B59: =IFERROR(__xludf.DUMMYFUNCTION("iferror(filter('Статьи'!$A$1:$A177,'Статьи'!$B$1:$B177=$B$58))"),"Зарплата производственного персонала") -> Зарплата производственного персонала | I59: =SUM(C59:H59) -> 0 | P59: =SUM(J59:K59) -> 0 | Q59: =I59-P59 -> 0 | R59: =IFERROR(I59/P59,0) -> 0 | S59: =IF(Q59=0,"",IF(R59=0,"обратить внимание",IF(R59>1,"перерасход","экономия")))
A60: =IFERROR(VLOOKUP(B60,'Статьи'!$A$2:C82,3,0)," ") -> ДДС отчетного месяца. Без НДС! | B60: =IFERROR(__xludf.DUMMYFUNCTION("""COMPUTED_VALUE"""),"Таможенные расходы") -> Таможенные расходы | I60: =SUM(C60:H60) -> 0 | P60: =SUM(J60:K60) -> 0 | Q60: =I60-P60 -> 0 | R60: =IFERROR(I60/P60,0) -> 0 | S60: =IF(Q60=0,"",IF(R60=0,"обратить внимание",IF(R60>1,"перерасход","экономия")))
A61: =IFERROR(VLOOKUP(B61,'Статьи'!$A$2:C83,3,0)," ") | I61: =SUM(C61:H61) -> 0 | P61: =SUM(J61:K61) -> 0 | Q61: =I61-P61 -> 0 | R61: =IFERROR(I61/P61,0) -> 0 | S61: =IF(Q61=0,"",IF(R61=0,"обратить внимание",IF(R61>1,"перерасход","экономия")))
A62: =IFERROR(VLOOKUP(B62,'Статьи'!$A$2:C84,3,0)," ") | I62: =SUM(C62:H62) -> 0 | P62: =SUM(J62:K62) -> 0 | Q62: =I62-P62 -> 0 | R62: =IFERROR(I62/P62,0) -> 0 | S62: =IF(Q62=0,"",IF(R62=0,"обратить внимание",IF(R62>1,"перерасход","экономия")))
A63: =IFERROR(VLOOKUP(B63,'Статьи'!$A$2:C85,3,0)," ") | I63: =SUM(C63:H63) -> 0 | P63: =SUM(J63:K63) -> 0 | Q63: =I63-P63 -> 0 | R63: =IFERROR(I63/P63,0) -> 0 | S63: =IF(Q63=0,"",IF(R63=0,"обратить внимание",IF(R63>1,"перерасход","экономия")))
A64: =IFERROR(VLOOKUP(B64,'Статьи'!$A$2:C86,3,0)," ") | I64: =SUM(C64:H64) -> 0 | P64: =SUM(J64:K64) -> 0 | Q64: =I64-P64 -> 0 | R64: =IFERROR(I64/P64,0) -> 0 | S64: =IF(Q64=0,"",IF(R64=0,"обратить внимание",IF(R64>1,"перерасход","экономия")))
A65: =IFERROR(VLOOKUP(B65,'Статьи'!$A$2:C87,3,0)," ") | I65: =SUM(C65:H65) -> 0 | P65: =SUM(J65:K65) -> 0 | Q65: =I65-P65 -> 0 | R65: =IFERROR(I65/P65,0) -> 0 | S65: =IF(Q65=0,"",IF(R65=0,"обратить внимание",IF(R65>1,"перерасход","экономия")))
...

Sheet 5
C1: ФАКТ | J1: План | Q1: Отклонения
A2: Источники | C2: {=TRANSPOSE('Справочник'!D2:D7)} -> ООО "Весело живем" | D2: ООО "Некогда грустить" | E2: 3 | F2: 4 | G2: 5 | H2: 6 | I2: Итого | J2: {=TRANSPOSE('Справочник'!D2:D7)} -> ООО "Весело живем" | K2: ООО "Некогда грустить" | L2: 3 | M2: 4 | N2: 5 | O2: 6 | P2: Итого | Q2: факт-план, EUR | R2: факт/план, % | S2: Результат
B3: Выручка | C3: =SUM(C4:C10) -> 5 | D3: =SUM(D4:D10) -> 0 | E3: =SUM(E4:E10) -> 0 | F3: =SUM(F4:F10) -> 0 | G3: =SUM(G4:G10) -> 0 | H3: =SUM(H4:H10) -> 0 | I3: =sum(C3:H3) -> 5 | J3: =SUM(J4:J10) -> 0 | K3: =SUM(K4:K10) -> 0 | P3: =SUM(P4:P10) -> 0 | Q3: =I3-P3 -> 5 | R3: =IFERROR(I3/P3,0) -> 0 | S3: =IF(Q3=0,"",IF(R3>1,"выполнение","план не выполнен")) -> план не выполнен
A4: =IFERROR(VLOOKUP(B4,'Статьи'!$A$2:C26,3,0)," ") -> 1С сч 90.01 убрать НДС! | B4: =IFERROR(__xludf.DUMMYFUNCTION("iferror(filter('Статьи'!$A$1:$A177,'Статьи'!$B$1:$B177=$B$3))"),"Выручка от аренды машиноместа") -> Выручка от аренды машиноместа | C4: 5 | I4: =SUM(C4:H4) -> 5 | P4: =SUM(J4:K4) -> 0 | Q4: =I4-P4 -> 5 | R4: =IFERROR(I4/P4,0) -> 0 | S4: =IF(Q4=0,"",IF(R4=0,"обратить внимание",IF(R4>1,"выполнение","план не выполнен"))) -> обратить внимание
A5: =IFERROR(VLOOKUP(B5,'Статьи'!$A$2:C27,3,0)," ") -> 1С сч 90.01 убрать НДС! | B5: =IFERROR(__xludf.DUMMYFUNCTION("""COMPUTED_VALUE"""),"Выручка за грузоперевозки") -> Выручка за грузоперевозки | I5: =SUM(C5:H5) -> 0 | P5: =SUM(J5:K5) -> 0 | Q5: =I5-P5 -> 0 | R5: =IFERROR(I5/P5,0) -> 0 | S5: =IF(Q5=0,"",IF(R5=0,"обратить внимание",IF(R5>1,"выполнение","план не выполнен")))
A6: =IFERROR(VLOOKUP(B6,'Статьи'!$A$2:C28,3,0)," ") | I6: =SUM(C6:H6) -> 0 | P6: =SUM(F6:J6) -> 0 | Q6: =I6-P6 -> 0 | R6: =IFERROR(I6/P6,0) -> 0 | S6: =IF(Q6=0,"",IF(R6=0,"обратить внимание",IF(R6>1,"выполнение","план не выполнен")))
A7: =IFERROR(VLOOKUP(B7,'Статьи'!$A$2:C29,3,0)," ") | I7: =SUM(C7:H7) -> 0 | P7: =SUM(F7:J7) -> 0 | Q7: =I7-P7 -> 0 | R7: =IFERROR(I7/P7,0) -> 0 | S7: =IF(Q7=0,"",IF(R7=0,"обратить внимание",IF(R7>1,"выполнение","план не выполнен")))
A8: =IFERROR(VLOOKUP(B8,'Статьи'!$A$2:C30,3,0)," ") | I8: =SUM(C8:H8) -> 0 | P8: =SUM(F8:J8) -> 0 | Q8: =I8-P8 -> 0 | R8: =IFERROR(I8/P8,0) -> 0 | S8: =IF(Q8=0,"",IF(R8=0,"обратить внимание",IF(R8>1,"выполнение","план не выполнен")))
A9: =IFERROR(VLOOKUP(B9,'Статьи'!$A$2:C31,3,0)," ") | Q9: =I9-P9 -> 0 | R9: =IFERROR(I9/P9,0) -> 0 | S9: =IF(Q9=0,"",IF(R9=0,"обратить внимание",IF(R9>1,"выполнение","план не выполнен")))
A10: =IFERROR(VLOOKUP(B10,'Статьи'!$A$2:C32,3,0)," ") | Q10: =I10-P10 -> 0 | R10: =IFERROR(I10/P10,0) -> 0 | S10: =IF(Q10=0,"",IF(R10=0,"обратить внимание",IF(R10>1,"выполнение","план не выполнен")))
B11: Производственные расходы | C11: =C12+C58 -> 0 | D11: =D12+D58 -> 0 | E11: =E12+E58 -> 0 | F11: =F12+F58 -> 0 | G11: =G12+G58 -> 0 | H11: =H12+H58 -> 0 | I11: =I12+I58 -> 0 | J11: =J12+J58 -> 0 | K11: =K12+K58 -> 0 | P11: =P12+P58 -> 0 | Q11: =I11-P11 -> 0 | R11: =IFERROR(I11/P11,0) -> 0 | S11: =IF(Q11=0,"",IF(R11>1,"план не выполнен","выполнение"))
B12: Переменные | C12: =sum(C13:C54) -> 0 | D12: =sum(D13:D54) -> 0 | E12: =sum(E13:E54) -> 0 | F12: =sum(F13:F54) -> 0 | G12: =sum(G13:G54) -> 0 | H12: =sum(H13:H54) -> 0 | I12: =sum(I13:I54) -> 0 | J12: =sum(J13:J54) -> 0 | K12: =sum(K13:K54) -> 0 | P12: =sum(P13:P54) -> 0 | Q12: =I12-P12 -> 0 | R12: =IFERROR(I12/P12,0) -> 0 | S12: =IF(Q12=0,"",IF(R12=0,"обратить внимание",IF(R12>1,"перерасход","экономия")))
A13: =IFERROR(VLOOKUP(B13,'Статьи'!$A$2:C35,3,0)," ") -> ДДС отчетного месяца. Без НДС! | B13: =IFERROR(__xludf.DUMMYFUNCTION("iferror(filter('Статьи'!$A$1:$A177,'Статьи'!$B$1:$B177=$B$12))"),"Комиссия топливных компаний") -> Комиссия топливных компаний | I13: =sum(C13:H13) -> 0 | P13: =SUM(J13:K13) -> 0 | Q13: =I13-P13 -> 0 | R13: =IFERROR(I13/P13,0) -> 0 | S13: =IF(Q13=0,"",IF(R13=0,"обратить внимание",IF(R13>1,"перерасход","экономия")))
A14: =IFERROR(VLOOKUP(B14,'Статьи'!$A$2:C36,3,0)," ") -> 1С | B14: =IFERROR(__xludf.DUMMYFUNCTION("""COMPUTED_VALUE"""),"Топливо для грузовых авто ") -> Топливо для грузовых авто | I14: =sum(C14:H14) -> 0 | P14: =SUM(J14:K14) -> 0 | Q14: =I14-P14 -> 0 | R14: =IFERROR(I14/P14,0) -> 0 | S14: =IF(Q14=0,"",IF(R14=0,"обратить внимание",IF(R14>1,"перерасход","экономия")))
A15: =IFERROR(VLOOKUP(B15,'Статьи'!$A$2:C37,3,0)," ") | I15: =sum(C15:H15) -> 0 | P15: =SUM(J15:K15) -> 0 | Q15: =I15-P15 -> 0 | R15: =IFERROR(I15/P15,0) -> 0 | S15: =IF(Q15=0,"",IF(R15=0,"обратить внимание",IF(R15>1,"перерасход","экономия")))
A16: =IFERROR(VLOOKUP(B16,'Статьи'!$A$2:C38,3,0)," ") | I16: =sum(C16:H16) -> 0 | P16: =SUM(J16:K16) -> 0 | Q16: =I16-P16 -> 0 | R16: =IFERROR(I16/P16,0) -> 0 | S16: =IF(Q16=0,"",IF(R16=0,"обратить внимание",IF(R16>1,"перерасход","экономия")))
A17: =IFERROR(VLOOKUP(B17,'Статьи'!$A$2:C39,3,0)," ") | I17: =sum(C17:H17) -> 0 | P17: =sum(F17:J17) -> 0 | Q17: =I17-P17 -> 0 | R17: =IFERROR(I17/P17,0) -> 0 | S17: =IF(Q17=0,"",IF(R17=0,"обратить внимание",IF(R17>1,"перерасход","экономия")))
I18: =sum(C18:H18) -> 0 | P18: =sum(F18:J18) -> 0 | Q18: =I18-P18 -> 0 | R18: =IFERROR(I18/P18,0) -> 0 | S18: =IF(Q18=0,0,IF(R18>1,"перерасход","экономия")) -> 0
